Workbook

Sheet Resumo
A1: Formulário | B1: Enviados | C1: % | D1: Atrasados | E1: % | F1: Sem Técnico | G1: % | H1: Duplicado | I1: % | J1: Total | L1: Formulários | M1: Enviado | N1: Atrasado | O1: Sem Téc | AD1: Form 1 | AG1: Form 2 | AJ1: Form 3
A2: 1 - Município | B2: =COUNTIF(AE2:AE56,"Enviado") | C2: =B2/SUM($B2,$D2,$F2,$H2) | D2: =COUNTIF(AE2:AE56,"Atrasado") | E2: =D2/SUM($B2,$D2,$F2,$H2) | F2: =COUNTIF(AE2:AE56,"Sem Técnico") | G2: =F2/SUM($B2,$D2,$F2,$H2) | H2: =COUNTIF(AE2:AE56,"Duplicado") | I2: =H2/SUM($B2,$D2,$F2,$H2) | J2: =SUM(B2,D2,F2,H2) | L2: 1 - Município | M2: =B2+H2 | N2: =D2 | O2: =F2 | AD2: {=_xlfn.UNIQUE(INDIRECT("'Form 1 - Município'!B2:B70"))} | AE2: =VLOOKUP(AD2,INDIRECT("'Form 1 - Município'!$B$2:$E$70"),4,FALSE) | AG2: {=_xlfn.UNIQUE(INDIRECT("'Form 2 - UVR'!B2:B70"))} | AH2: =VLOOKUP(AG2,INDIRECT("'Form 2 - UVR'!$B$2:$E$70"),4,FALSE) | AJ2: {=_xlfn.UNIQUE(INDIRECT("'Form 3 - Empreendimento'!B2:B70"))} | AK2: =VLOOKUP(AJ2,INDIRECT("'Form 3 - Empreendimento'!$B$2:$E$70"),4,FALSE)
A3: 2 - UVR | B3: =COUNTIF(AH2:AH56,"Enviado") | C3: =B3/SUM($B3,$D3,$F3,$H3) | D3: =COUNTIF(AH2:AH56,"Atrasado") | E3: =D3/SUM($B3,$D3,$F3,$H3) | F3: =COUNTIF(AH2:AH56,"Sem Técnico") | G3: =F3/SUM($B3,$D3,$F3,$H3) | H3: =COUNTIF(AH2:AH56,"Duplicado") | I3: =H3/SUM($B3,$D3,$F3,$H3) | J3: =SUM(B3,D3,F3,H3) | L3: 2 - UVR | M3: =B3+H3 | N3: =D3 | O3: =F3 | AD3: = | AE3: =VLOOKUP(AD3,INDIRECT("'Form 1 - Município'!$B$2:$E$70"),4,FALSE) | AG3: = | AH3: =VLOOKUP(AG3,INDIRECT("'Form 2 - UVR'!$B$2:$E$70"),4,FALSE) | AJ3: = | AK3: =VLOOKUP(AJ3,INDIRECT("'Form 3 - Empreendimento'!$B$2:$E$70"),4,FALSE)
A4: 3 - Empreendimento | B4: =COUNTIF(AK2:AK56,"Enviado") | C4: =B4/SUM($B4,$D4,$F4,$H4) | D4: =COUNTIF(AK2:AK56,"Atrasado") | E4: =D4/SUM($B4,$D4,$F4,$H4) | F4: =COUNTIF(AK2:AK56,"Sem Técnico") | G4: =F4/SUM($B4,$D4,$F4,$H4) | H4: =COUNTIF(AK2:AK56,"Duplicado") | I4: =H4/SUM($B4,$D4,$F4,$H4) | J4: =SUM(B4,D4,F4,H4) | L4: 3 - Empreendimento | M4: =B4+H4 | N4: =D4 | O4: =F4 | AD4: = | AE4: =VLOOKUP(AD4,INDIRECT("'Form 1 - Município'!$B$2:$E$70"),4,FALSE) | AG4: = | AH4: =VLOOKUP(AG4,INDIRECT("'Form 2 - UVR'!$B$2:$E$70"),4,FALSE) | AJ4: = | AK4: =VLOOKUP(AJ4,INDIRECT("'Form 3 - Empreendimento'!$B$2:$E$70"),4,FALSE)
A5: Total | B5: =SUM(B2:B4) | C5: =B5/SUM($B5,$D5,$F5,$H5) | D5: =SUM(D2:D4) | E5: =D5/SUM($B5,$D5,$F5,$H5) | F5: =SUM(F2:F4) | G5: =F5/SUM($B5,$D5,$F5,$H5) | H5: =SUM(H2:H4) | I5: =H5/SUM($B5,$D5,$F5,$H5) | J5: =SUM(J2:J4) | AD5: = | AE5: =VLOOKUP(AD5,INDIRECT("'Form 1 - Município'!$B$2:$E$70"),4,FALSE) | AG5: = | AH5: =VLOOKUP(AG5,INDIRECT("'Form 2 - UVR'!$B$2:$E$70"),4,FALSE) | AJ5: = | AK5: =VLOOKUP(AJ5,INDIRECT("'Form 3 - Empreendimento'!$B$2:$E$70"),4,FALSE)
AD6: = | AE6: =VLOOKUP(AD6,INDIRECT("'Form 1 - Município'!$B$2:$E$70"),4,FALSE) | AG6: = | AH6: =VLOOKUP(AG6,INDIRECT("'Form 2 - UVR'!$B$2:$E$70"),4,FALSE) | AJ6: = | AK6: =VLOOKUP(AJ6,INDIRECT("'Form 3 - Empreendimento'!$B$2:$E$70"),4,FALSE)
AD7: = | AE7: =VLOOKUP(AD7,INDIRECT("'Form 1 - Município'!$B$2:$E$70"),4,FALSE) | AG7: = | AH7: =VLOOKUP(AG7,INDIRECT("'Form 2 - UVR'!$B$2:$E$70"),4,FALSE) | AJ7: = | AK7: =VLOOKUP(AJ7,INDIRECT("'Form 3 - Empreendimento'!$B$2:$E$70"),4,FALSE)
AD8: = | AE8: =VLOOKUP(AD8,INDIRECT("'Form 1 - Município'!$B$2:$E$70"),4,FALSE) | AG8: = | AH8: =VLOOKUP(AG8,INDIRECT("'Form 2 - UVR'!$B$2:$E$70"),4,FALSE) | AJ8: = | AK8: =VLOOKUP(AJ8,INDIRECT("'Form 3 - Empreendimento'!$B$2:$E$70"),4,FALSE)
A9: Formulário | B9: Validados | C9: % | AD9: = | AE9: =VLOOKUP(AD9,INDIRECT("'Form 1 - Município'!$B$2:$E$70"),4,FALSE) | AG9: = | AH9: =VLOOKUP(AG9,INDIRECT("'Form 2 - UVR'!$B$2:$E$70"),4,FALSE) | AJ9: = | AK9: =VLOOKUP(AJ9,INDIRECT("'Form 3 - Empreendimento'!$B$2:$E$70"),4,FALSE)
A10: 1 - Município | B10: =COUNTIF(INDIRECT("'Form 1 - Município'!G2:G100"),"Sim") | C10: =$B$10/(COUNTA(INDIRECT("'Form 1 - Município'!B2:B70"))) | AD10: = | AE10: =VLOOKUP(AD10,INDIRECT("'Form 1 - Município'!$B$2:$E$70"),4,FALSE) | AG10: = | AH10: =VLOOKUP(AG10,INDIRECT("'Form 2 - UVR'!$B$2:$E$70"),4,FALSE) | AJ10: = | AK10: =VLOOKUP(AJ10,INDIRECT("'Form 3 - Empreendimento'!$B$2:$E$70"),4,FALSE)
A11: 2 - UVR | B11: =COUNTIF(INDIRECT("'Form 2 - UVR'!G2:G100"),"Sim") | C11: =$B$11/(COUNTA(INDIRECT("'Form 2 - UVR'!B2:B70"))) | AD11: = | AE11: =VLOOKUP(AD11,INDIRECT("'Form 1 - Município'!$B$2:$E$70"),4,FALSE) | AG11: = | AH11: =VLOOKUP(AG11,INDIRECT("'Form 2 - UVR'!$B$2:$E$70"),4,FALSE) | AJ11: = | AK11: =VLOOKUP(AJ11,INDIRECT("'Form 3 - Empreendimento'!$B$2:$E$70"),4,FALSE)
A12: 3 - Empreendimento | B12: =COUNTIF(INDIRECT("'Form 3 - Empreendimento'!G2:G100"),"Sim") | C12: =$B$12/(COUNTA(INDIRECT("'Form 3 - Empreendimento'!B2:B70"))) | AD12: = | AE12: =VLOOKUP(AD12,INDIRECT("'Form 1 - Município'!$B$2:$E$70"),4,FALSE) | AG12: = | AH12: =VLOOKUP(AG12,INDIRECT("'Form 2 - UVR'!$B$2:$E$70"),4,FALSE) | AJ12: = | AK12: =VLOOKUP(AJ12,INDIRECT("'Form 3 - Empreendimento'!$B$2:$E$70"),4,FALSE)
AD13: = | AE13: =VLOOKUP(AD13,INDIRECT("'Form 1 - Município'!$B$2:$E$70"),4,FALSE) | AG13: = | AH13: =VLOOKUP(AG13,INDIRECT("'Form 2 - UVR'!$B$2:$E$70"),4,FALSE) | AJ13: = | AK13: =VLOOKUP(AJ13,INDIRECT("'Form 3 - Empreendimento'!$B$2:$E$70"),4,FALSE)
AD14: = | AE14: =VLOOKUP(AD14,INDIRECT("'Form 1 - Município'!$B$2:$E$70"),4,FALSE) | AG14: = | AH14: =VLOOKUP(AG14,INDIRECT("'Form 2 - UVR'!$B$2:$E$70"),4,FALSE) | AJ14: = | AK14: =VLOOKUP(AJ14,INDIRECT("'Form 3 - Empreendimento'!$B$2:$E$70"),4,FALSE)
A15: Regional | B15: Form 1 - Município | D15: Form 2 - UVR | F15: Form 3 - Empreendimento | AD15: = | AE15: =VLOOKUP(AD15,INDIRECT("'Form 1 - Município'!$B$2:$E$70"),4,FALSE) | AG15: = | AH15: =VLOOKUP(AG15,INDIRECT("'Form 2 - UVR'!$B$2:$E$70"),4,FALSE) | AJ15: = | AK15: =VLOOKUP(AJ15,INDIRECT("'Form 3 - Empreendimento'!$B$2:$E$70"),4,FALSE)
B16: Validados | C16: % | D16: Validados | E16: % | F16: Validados | G16: % | AD16: = | AE16: =VLOOKUP(AD16,INDIRECT("'Form 1 - Município'!$B$2:$E$70"),4,FALSE) | AG16: = | AH16: =VLOOKUP(AG16,INDIRECT("'Form 2 - UVR'!$B$2:$E$70"),4,FALSE) | AJ16: = | AK16: =VLOOKUP(AJ16,INDIRECT("'Form 3 - Empreendimento'!$B$2:$E$70"),4,FALSE)
A17: Bianca | B17: {=IFERROR(ROWS(_xlfn._xlws.FILTER(INDIRECT("'"&B$15&"'!A2:K100"),(INDIRECT("'"&B$15&"'!A2:A100")=$A17) * (INDIRECT("'"&B$15&"'!G2:G100")="Sim"))), 0)} | C17: =B17/(COUNTA(INDIRECT("'Form 1 - Município'!B2:B70"))) | D17: {=IFERROR(ROWS(_xlfn._xlws.FILTER(INDIRECT("'"&D$15&"'!A2:K100"),(INDIRECT("'"&D$15&"'!A2:A100")=$A17) * (INDIRECT("'"&D$15&"'!G2:G100")="Sim"))), 0)} | E17: =D17/(COUNTA(INDIRECT("'Form 2 - UVR'!B2:B70"))) | F17: {=IFERROR(ROWS(_xlfn._xlws.FILTER(INDIRECT("'"&F$15&"'!A2:K100"),(INDIRECT("'"&F$15&"'!A2:A100")=$A17) * (INDIRECT("'"&F$15&"'!G2:G100")="Sim"))), 0)} | G17: =F17/(COUNTA(INDIRECT("'Form 3 - Empreendimento'!B2:B70"))) | AD17: = | AE17: =VLOOKUP(AD17,INDIRECT("'Form 1 - Município'!$B$2:$E$70"),4,FALSE) | AG17: = | AH17: =VLOOKUP(AG17,INDIRECT("'Form 2 - UVR'!$B$2:$E$70"),4,FALSE) | AJ17: = | AK17: =VLOOKUP(AJ17,INDIRECT("'Form 3 - Empreendimento'!$B$2:$E$70"),4,FALSE)
A18: Gabriel | B18: {=IFERROR(ROWS(_xlfn._xlws.FILTER(INDIRECT("'"&B$15&"'!A2:K100"),(INDIRECT("'"&B$15&"'!A2:A100")=$A18) * (INDIRECT("'"&B$15&"'!G2:G100")="Sim"))), 0)} | C18: =B18/(COUNTA(INDIRECT("'Form 1 - Município'!B2:B70"))) | D18: {=IFERROR(ROWS(_xlfn._xlws.FILTER(INDIRECT("'"&D$15&"'!A2:K100"),(INDIRECT("'"&D$15&"'!A2:A100")=$A18) * (INDIRECT("'"&D$15&"'!G2:G100")="Sim"))), 0)} | E18: =D18/(COUNTA(INDIRECT("'Form 2 - UVR'!B2:B70"))) | F18: {=IFERROR(ROWS(_xlfn._xlws.FILTER(INDIRECT("'"&F$15&"'!A2:K100"),(INDIRECT("'"&F$15&"'!A2:A100")=$A18) * (INDIRECT("'"&F$15&"'!G2:G100")="Sim"))), 0)} | G18: =F18/(COUNTA(INDIRECT("'Form 3 - Empreendimento'!B2:B70"))) | AD18: = | AE18: =VLOOKUP(AD18,INDIRECT("'Form 1 - Município'!$B$2:$E$70"),4,FALSE) | AG18: = | AH18: =VLOOKUP(AG18,INDIRECT("'Form 2 - UVR'!$B$2:$E$70"),4,FALSE) | AJ18: = | AK18: =VLOOKUP(AJ18,INDIRECT("'Form 3 - Empreendimento'!$B$2:$E$70"),4,FALSE)
A19: Gustavo | B19: {=IFERROR(ROWS(_xlfn._xlws.FILTER(INDIRECT("'"&B$15&"'!A2:K100"),(INDIRECT("'"&B$15&"'!A2:A100")=$A19) * (INDIRECT("'"&B$15&"'!G2:G100")="Sim"))), 0)} | C19: =B19/(COUNTA(INDIRECT("'Form 1 - Município'!B2:B70"))) | D19: {=IFERROR(ROWS(_xlfn._xlws.FILTER(INDIRECT("'"&D$15&"'!A2:K100"),(INDIRECT("'"&D$15&"'!A2:A100")=$A19) * (INDIRECT("'"&D$15&"'!G2:G100")="Sim"))), 0)} | E19: =D19/(COUNTA(INDIRECT("'Form 2 - UVR'!B2:B70"))) | F19: {=IFERROR(ROWS(_xlfn._xlws.FILTER(INDIRECT("'"&F$15&"'!A2:K100"),(INDIRECT("'"&F$15&"'!A2:A100")=$A19) * (INDIRECT("'"&F$15&"'!G2:G100")="Sim"))), 0)} | G19: =F19/(COUNTA(INDIRECT("'Form 3 - Empreendimento'!B2:B70"))) | AD19: = | AE19: =VLOOKUP(AD19,INDIRECT("'Form 1 - Município'!$B$2:$E$70"),4,FALSE) | AG19: = | AH19: =VLOOKUP(AG19,INDIRECT("'Form 2 - UVR'!$B$2:$E$70"),4,FALSE) | AJ19: = | AK19: =VLOOKUP(AJ19,INDIRECT("'Form 3 - Empreendimento'!$B$2:$E$70"),4,FALSE)
A20: Larissa | B20: {=IFERROR(ROWS(_xlfn._xlws.FILTER(INDIRECT("'"&B$15&"'!A2:K100"),(INDIRECT("'"&B$15&"'!A2:A100")=$A20) * (INDIRECT("'"&B$15&"'!G2:G100")="Sim"))), 0)} | C20: =B20/(COUNTA(INDIRECT("'Form 1 - Município'!B2:B70"))) | D20: {=IFERROR(ROWS(_xlfn._xlws.FILTER(INDIRECT("'"&D$15&"'!A2:K100"),(INDIRECT("'"&D$15&"'!A2:A100")=$A20) * (INDIRECT("'"&D$15&"'!G2:G100")="Sim"))), 0)} | E20: =D20/(COUNTA(INDIRECT("'Form 2 - UVR'!B2:B70"))) | F20: {=IFERROR(ROWS(_xlfn._xlws.FILTER(INDIRECT("'"&F$15&"'!A2:K100"),(INDIRECT("'"&F$15&"'!A2:A100")=$A20) * (INDIRECT("'"&F$15&"'!G2:G100")="Sim"))), 0)} | G20: =F20/(COUNTA(INDIRECT("'Form 3 - Empreendimento'!B2:B70"))) | AD20: = | AE20: =VLOOKUP(AD20,INDIRECT("'Form 1 - Município'!$B$2:$E$70"),4,FALSE) | AG20: = | AH20: =VLOOKUP(AG20,INDIRECT("'Form 2 - UVR'!$B$2:$E$70"),4,FALSE) | AJ20: = | AK20: =VLOOKUP(AJ20,INDIRECT("'Form 3 - Empreendimento'!$B$2:$E$70"),4,FALSE)
A21: Luana | B21: {=IFERROR(ROWS(_xlfn._xlws.FILTER(INDIRECT("'"&B$15&"'!A2:K100"),(INDIRECT("'"&B$15&"'!A2:A100")=$A21) * (INDIRECT("'"&B$15&"'!G2:G100")="Sim"))), 0)} | C21: =B21/(COUNTA(INDIRECT("'Form 1 - Município'!B2:B70"))) | D21: {=IFERROR(ROWS(_xlfn._xlws.FILTER(INDIRECT("'"&D$15&"'!A2:K100"),(INDIRECT("'"&D$15&"'!A2:A100")=$A21) * (INDIRECT("'"&D$15&"'!G2:G100")="Sim"))), 0)} | E21: =D21/(COUNTA(INDIRECT("'Form 2 - UVR'!B2:B70"))) | F21: {=IFERROR(ROWS(_xlfn._xlws.FILTER(INDIRECT("'"&F$15&"'!A2:K100"),(INDIRECT("'"&F$15&"'!A2:A100")=$A21) * (INDIRECT("'"&F$15&"'!G2:G100")="Sim"))), 0)} | G21: =F21/(COUNTA(INDIRECT("'Form 3 - Empreendimento'!B2:B70"))) | AD21: = | AE21: =VLOOKUP(AD21,INDIRECT("'Form 1 - Município'!$B$2:$E$70"),4,FALSE) | AG21: = | AH21: =VLOOKUP(AG21,INDIRECT("'Form 2 - UVR'!$B$2:$E$70"),4,FALSE) | AJ21: = | AK21: =VLOOKUP(AJ21,INDIRECT("'Form 3 - Empreendimento'!$B$2:$E$70"),4,FALSE)
A22: Valquiria | B22: {=IFERROR(ROWS(_xlfn._xlws.FILTER(INDIRECT("'"&B$15&"'!A2:K100"),(INDIRECT("'"&B$15&"'!A2:A100")=$A22) * (INDIRECT("'"&B$15&"'!G2:G100")="Sim"))), 0)} | C22: =B22/(COUNTA(INDIRECT("'Form 1 - Município'!B2:B70"))) | D22: {=IFERROR(ROWS(_xlfn._xlws.FILTER(INDIRECT("'"&D$15&"'!A2:K100"),(INDIRECT("'"&D$15&"'!A2:A100")=$A22) * (INDIRECT("'"&D$15&"'!G2:G100")="Sim"))), 0)} | E22: =D22/(COUNTA(INDIRECT("'Form 2 - UVR'!B2:B70"))) | F22: {=IFERROR(ROWS(_xlfn._xlws.FILTER(INDIRECT("'"&F$15&"'!A2:K100"),(INDIRECT("'"&F$15&"'!A2:A100")=$A22) * (INDIRECT("'"&F$15&"'!G2:G100")="Sim"))), 0)} | G22: =F22/(COUNTA(INDIRECT("'Form 3 - Empreendimento'!B2:B70"))) | AD22: = | AE22: =VLOOKUP(AD22,INDIRECT("'Form 1 - Município'!$B$2:$E$70"),4,FALSE) | AG22: = | AH22: =VLOOKUP(AG22,INDIRECT("'Form 2 - UVR'!$B$2:$E$70"),4,FALSE) | AJ22: = | AK22: =VLOOKUP(AJ22,INDIRECT("'Form 3 - Empreendimento'!$B$2:$E$70"),4,FALSE)
A23: Total | B23: =SUM(B17:B22) | C23: =SUM(C17:C22) | D23: =SUM(D17:D22) | E23: =SUM(E17:E22) | F23: =SUM(F17:F22) | G23: =SUM(G17:G22) | AD23: = | AE23: =VLOOKUP(AD23,INDIRECT("'Form 1 - Município'!$B$2:$E$70"),4,FALSE) | AG23: = | AH23: =VLOOKUP(AG23,INDIRECT("'Form 2 - UVR'!$B$2:$E$70"),4,FALSE) | AJ23: = | AK23: =VLOOKUP(AJ23,INDIRECT("'Form 3 - Empreendimento'!$B$2:$E$70"),4,FALSE)
AD24: = | AE24: =VLOOKUP(AD24,INDIRECT("'Form 1 - Município'!$B$2:$E$70"),4,FALSE) | AG24: = | AH24: =VLOOKUP(AG24,INDIRECT("'Form 2 - UVR'!$B$2:$E$70"),4,FALSE) | AJ24: = | AK24: =VLOOKUP(AJ24,INDIRECT("'Form 3 - Empreendimento'!$B$2:$E$70"),4,FALSE)
AD25: = | AE25: =VLOOKUP(AD25,INDIRECT("'Form 1 - Município'!$B$2:$E$70"),4,FALSE) | AG25: = | AH25: =VLOOKUP(AG25,INDIRECT("'Form 2 - UVR'!$B$2:$E$70"),4,FALSE) | AJ25: = | AK25: =VLOOKUP(AJ25,INDIRECT("'Form 3 - Empreendimento'!$B$2:$E$70"),4,FALSE)
AD26: = | AE26: =VLOOKUP(AD26,INDIRECT("'Form 1 - Município'!$B$2:$E$70"),4,FALSE) | AG26: = | AH26: =VLOOKUP(AG26,INDIRECT("'Form 2 - UVR'!$B$2:$E$70"),4,FALSE) | AJ26: = | AK26: =VLOOKUP(AJ26,INDIRECT("'Form 3 - Empreendimento'!$B$2:$E$70"),4,FALSE)
AD27: = | AE27: =VLOOKUP(AD27,INDIRECT("'Form 1 - Município'!$B$2:$E$70"),4,FALSE) | AG27: = | AH27: =VLOOKUP(AG27,INDIRECT("'Form 2 - UVR'!$B$2:$E$70"),4,FALSE) | AJ27: = | AK27: =VLOOKUP(AJ27,INDIRECT("'Form 3 - Empreendimento'!$B$2:$E$70"),4,FALSE)
AD28: = | AE28: =VLOOKUP(AD28,INDIRECT("'Form 1 - Município'!$B$2:$E$70"),4,FALSE) | AG28: = | AH28: =VLOOKUP(AG28,INDIRECT("'Form 2 - UVR'!$B$2:$E$70"),4,FALSE) | AJ28: = | AK28: =VLOOKUP(AJ28,INDIRECT("'Form 3 - Empreendimento'!$B$2:$E$70"),4,FALSE)
AD29: = | AE29: =VLOOKUP(AD29,INDIRECT("'Form 1 - Município'!$B$2:$E$70"),4,FALSE) | AG29: = | AH29: =VLOOKUP(AG29,INDIRECT("'Form 2 - UVR'!$B$2:$E$70"),4,FALSE) | AJ29: = | AK29: =VLOOKUP(AJ29,INDIRECT("'Form 3 - Empreendimento'!$B$2:$E$70"),4,FALSE)
AD30: = | AE30: =VLOOKUP(AD30,INDIRECT("'Form 1 - Município'!$B$2:$E$70"),4,FALSE) | AG30: = | AH30: =VLOOKUP(AG30,INDIRECT("'Form 2 - UVR'!$B$2:$E$70"),4,FALSE) | AJ30: = | AK30: =VLOOKUP(AJ30,INDIRECT("'Form 3 - Empreendimento'!$B$2:$E$70"),4,FALSE)
AD31: = | AE31: =VLOOKUP(AD31,INDIRECT("'Form 1 - Município'!$B$2:$E$70"),4,FALSE) | AG31: = | AH31: =VLOOKUP(AG31,INDIRECT("'Form 2 - UVR'!$B$2:$E$70"),4,FALSE) | AJ31: = | AK31: =VLOOKUP(AJ31,INDIRECT("'Form 3 - Empreendimento'!$B$2:$E$70"),4,FALSE)
AD32: = | AE32: =VLOOKUP(AD32,INDIRECT("'Form 1 - Município'!$B$2:$E$70"),4,FALSE) | AG32: = | AH32: =VLOOKUP(AG32,INDIRECT("'Form 2 - UVR'!$B$2:$E$70"),4,FALSE) | AJ32: = | AK32: =VLOOKUP(AJ32,INDIRECT("'Form 3 - Empreendimento'!$B$2:$E$70"),4,FALSE)
AD33: = | AE33: =VLOOKUP(AD33,INDIRECT("'Form 1 - Município'!$B$2:$E$70"),4,FALSE) | AG33: = | AH33: =VLOOKUP(AG33,INDIRECT("'Form 2 - UVR'!$B$2:$E$70"),4,FALSE) | AJ33: = | AK33: =VLOOKUP(AJ33,INDIRECT("'Form 3 - Empreendimento'!$B$2:$E$70"),4,FALSE)
AD34: = | AE34: =VLOOKUP(AD34,INDIRECT("'Form 1 - Município'!$B$2:$E$70"),4,FALSE) | AG34: = | AH34: =VLOOKUP(AG34,INDIRECT("'Form 2 - UVR'!$B$2:$E$70"),4,FALSE) | AJ34: = | AK34: =VLOOKUP(AJ34,INDIRECT("'Form 3 - Empreendimento'!$B$2:$E$70"),4,FALSE)
AD35: = | AE35: =VLOOKUP(AD35,INDIRECT("'Form 1 - Município'!$B$2:$E$70"),4,FALSE) | AG35: = | AH35: =VLOOKUP(AG35,INDIRECT("'Form 2 - UVR'!$B$2:$E$70"),4,FALSE) | AJ35: = | AK35: =VLOOKUP(AJ35,INDIRECT("'Form 3 - Empreendimento'!$B$2:$E$70"),4,FALSE)
... AD56: = | AE56: =VLOOKUP(AD56,INDIRECT("'Form 1 - Município'!$B$2:$E$70"),4,FALSE) | AG56: = | AH56: =VLOOKUP(AG56,INDIRECT("'Form 2 - UVR'!$B$2:$E$70"),4,FALSE) | AJ56: = | AK56: =VLOOKUP(AJ56,INDIRECT("'Form 3 - Empreendimento'!$B$2:$E$70"),4,FALSE)

Sheet Monitoramento
A1: Regional | B1: Municípios | C1: UVR | D1: Form 1 - Município | E1: Form 2 - UVR | F1: Form 3 - Empreendimento
A2: Bianca | B2: Anahy | C2: 1 | D2: {=IF( VLOOKUP( $A2, _xlfn._xlws.FILTER( INDIRECT("'"&D$1&"'!A2:E1000"), (INDIRECT("'"&D$1&"'!B2:B1000")=$B2) * (INDIRECT("'"&D$1&"'!C2:C1000")=$C2) ), 5, FALSE )=0, "", VLOOKUP( $A2, _xlfn._xlws.FILTER( INDIRECT("'"&D$1&"'!A2:E1000"), (INDIRECT("'"&D$1&"'!B2:B1000")=$B2) * (INDIRECT("'"&D$1&"'!C2:C1000")=$C2) ), 5, FALSE ) )} | E2: {=IF( VLOOKUP( $A2, _xlfn._xlws.FILTER( INDIRECT("'"&E$1&"'!A2:E1000"), (INDIRECT("'"&E$1&"'!B2:B1000")=$B2) * (INDIRECT("'"&E$1&"'!C2:C1000")=$C2) ), 5, FALSE )=0, "", VLOOKUP( $A2, _xlfn._xlws.FILTER( INDIRECT("'"&E$1&"'!A2:E1000"), (INDIRECT("'"&E$1&"'!B2:B1000")=$B2) * (INDIRECT("'"&E$1&"'!C2:C1000")=$C2) ), 5, FALSE ) )} | F2: {=IF( VLOOKUP( $A2, _xlfn._xlws.FILTER( INDIRECT("'"&F$1&"'!A2:E1000"), (INDIRECT("'"&F$1&"'!B2:B1000")=$B2) * (INDIRECT("'"&F$1&"'!C2:C1000")=$C2) ), 5, FALSE )=0, "", VLOOKUP( $A2, _xlfn._xlws.FILTER( INDIRECT("'"&F$1&"'!A2:E1000"), (INDIRECT("'"&F$1&"'!B2:B1000")=$B2) * (INDIRECT("'"&F$1&"'!C2:C1000")=$C2) ), 5, FALSE ) )}
A3: Bianca | B3: Boa Vista da Aparecida | C3: 1 | D3: {=IF( VLOOKUP( $A3, _xlfn._xlws.FILTER( INDIRECT("'"&D$1&"'!A2:E1000"), (INDIRECT("'"&D$1&"'!B2:B1000")=$B3) * (INDIRECT("'"&D$1&"'!C2:C1000")=$C3) ), 5, FALSE )=0, "", VLOOKUP( $A3, _xlfn._xlws.FILTER( INDIRECT("'"&D$1&"'!A2:E1000"), (INDIRECT("'"&D$1&"'!B2:B1000")=$B3) * (INDIRECT("'"&D$1&"'!C2:C1000")=$C3) ), 5, FALSE ) )} | E3: {=IF( VLOOKUP( $A3, _xlfn._xlws.FILTER( INDIRECT("'"&E$1&"'!A2:E1000"), (INDIRECT("'"&E$1&"'!B2:B1000")=$B3) * (INDIRECT("'"&E$1&"'!C2:C1000")=$C3) ), 5, FALSE )=0, "", VLOOKUP( $A3, _xlfn._xlws.FILTER( INDIRECT("'"&E$1&"'!A2:E1000"), (INDIRECT("'"&E$1&"'!B2:B1000")=$B3) * (INDIRECT("'"&E$1&"'!C2:C1000")=$C3) ), 5, FALSE ) )} | F3: {=IF( VLOOKUP( $A3, _xlfn._xlws.FILTER( INDIRECT("'"&F$1&"'!A2:E1000"), (INDIRECT("'"&F$1&"'!B2:B1000")=$B3) * (INDIRECT("'"&F$1&"'!C2:C1000")=$C3) ), 5, FALSE )=0, "", VLOOKUP( $A3, _xlfn._xlws.FILTER( INDIRECT("'"&F$1&"'!A2:E1000"), (INDIRECT("'"&F$1&"'!B2:B1000")=$B3) * (INDIRECT("'"&F$1&"'!C2:C1000")=$C3) ), 5, FALSE ) )}
A4: Bianca | B4: Braganey | C4: 1 | D4: {=IF( VLOOKUP( $A4, _xlfn._xlws.FILTER( INDIRECT("'"&D$1&"'!A2:E1000"), (INDIRECT("'"&D$1&"'!B2:B1000")=$B4) * (INDIRECT("'"&D$1&"'!C2:C1000")=$C4) ), 5, FALSE )=0, "", VLOOKUP( $A4, _xlfn._xlws.FILTER( INDIRECT("'"&D$1&"'!A2:E1000"), (INDIRECT("'"&D$1&"'!B2:B1000")=$B4) * (INDIRECT("'"&D$1&"'!C2:C1000")=$C4) ), 5, FALSE ) )} | E4: {=IF( VLOOKUP( $A4, _xlfn._xlws.FILTER( INDIRECT("'"&E$1&"'!A2:E1000"), (INDIRECT("'"&E$1&"'!B2:B1000")=$B4) * (INDIRECT("'"&E$1&"'!C2:C1000")=$C4) ), 5, FALSE )=0, "", VLOOKUP( $A4, _xlfn._xlws.FILTER( INDIRECT("'"&E$1&"'!A2:E1000"), (INDIRECT("'"&E$1&"'!B2:B1000")=$B4) * (INDIRECT("'"&E$1&"'!C2:C1000")=$C4) ), 5, FALSE ) )} | F4: {=IF( VLOOKUP( $A4, _xlfn._xlws.FILTER( INDIRECT("'"&F$1&"'!A2:E1000"), (INDIRECT("'"&F$1&"'!B2:B1000")=$B4) * (INDIRECT("'"&F$1&"'!C2:C1000")=$C4) ), 5, FALSE )=0, "", VLOOKUP( $A4, _xlfn._xlws.FILTER( INDIRECT("'"&F$1&"'!A2:E1000"), (INDIRECT("'"&F$1&"'!B2:B1000")=$B4) * (INDIRECT("'"&F$1&"'!C2:C1000")=$C4) ), 5, FALSE ) )}
A5: Bianca | B5: Campo Bonito | C5: 1 | D5: {=IF( VLOOKUP( $A5, _xlfn._xlws.FILTER( INDIRECT("'"&D$1&"'!A2:E1000"), (INDIRECT("'"&D$1&"'!B2:B1000")=$B5) * (INDIRECT("'"&D$1&"'!C2:C1000")=$C5) ), 5, FALSE )=0, "", VLOOKUP( $A5, _xlfn._xlws.FILTER( INDIRECT("'"&D$1&"'!A2:E1000"), (INDIRECT("'"&D$1&"'!B2:B1000")=$B5) * (INDIRECT("'"&D$1&"'!C2:C1000")=$C5) ), 5, FALSE ) )} | E5: {=IF( VLOOKUP( $A5, _xlfn._xlws.FILTER( INDIRECT("'"&E$1&"'!A2:E1000"), (INDIRECT("'"&E$1&"'!B2:B1000")=$B5) * (INDIRECT("'"&E$1&"'!C2:C1000")=$C5) ), 5, FALSE )=0, "", VLOOKUP( $A5, _xlfn._xlws.FILTER( INDIRECT("'"&E$1&"'!A2:E1000"), (INDIRECT("'"&E$1&"'!B2:B1000")=$B5) * (INDIRECT("'"&E$1&"'!C2:C1000")=$C5) ), 5, FALSE ) )} | F5: {=IF( VLOOKUP( $A5, _xlfn._xlws.FILTER( INDIRECT("'"&F$1&"'!A2:E1000"), (INDIRECT("'"&F$1&"'!B2:B1000")=$B5) * (INDIRECT("'"&F$1&"'!C2:C1000")=$C5) ), 5, FALSE )=0, "", VLOOKUP( $A5, _xlfn._xlws.FILTER( INDIRECT("'"&F$1&"'!A2:E1000"), (INDIRECT("'"&F$1&"'!B2:B1000")=$B5) * (INDIRECT("'"&F$1&"'!C2:C1000")=$C5) ), 5, FALSE ) )}
A6: Bianca | B6: Catanduvas | C6: 1 | D6: {=IF( VLOOKUP( $A6, _xlfn._xlws.FILTER( INDIRECT("'"&D$1&"'!A2:E1000"), (INDIRECT("'"&D$1&"'!B2:B1000")=$B6) * (INDIRECT("'"&D$1&"'!C2:C1000")=$C6) ), 5, FALSE )=0, "", VLOOKUP( $A6, _xlfn._xlws.FILTER( INDIRECT("'"&D$1&"'!A2:E1000"), (INDIRECT("'"&D$1&"'!B2:B1000")=$B6) * (INDIRECT("'"&D$1&"'!C2:C1000")=$C6) ), 5, FALSE ) )} | E6: {=IF( VLOOKUP( $A6, _xlfn._xlws.FILTER( INDIRECT("'"&E$1&"'!A2:E1000"), (INDIRECT("'"&E$1&"'!B2:B1000")=$B6) * (INDIRECT("'"&E$1&"'!C2:C1000")=$C6) ), 5, FALSE )=0, "", VLOOKUP( $A6, _xlfn._xlws.FILTER( INDIRECT("'"&E$1&"'!A2:E1000"), (INDIRECT("'"&E$1&"'!B2:B1000")=$B6) * (INDIRECT("'"&E$1&"'!C2:C1000")=$C6) ), 5, FALSE ) )} | F6: {=IF( VLOOKUP( $A6, _xlfn._xlws.FILTER( INDIRECT("'"&F$1&"'!A2:E1000"), (INDIRECT("'"&F$1&"'!B2:B1000")=$B6) * (INDIRECT("'"&F$1&"'!C2:C1000")=$C6) ), 5, FALSE )=0, "", VLOOKUP( $A6, _xlfn._xlws.FILTER( INDIRECT("'"&F$1&"'!A2:E1000"), (INDIRECT("'"&F$1&"'!B2:B1000")=$B6) * (INDIRECT("'"&F$1&"'!C2:C1000")=$C6) ), 5, FALSE ) )}
A7: Bianca | B7: Corbélia | C7: 1 | D7: {=IF( VLOOKUP( $A7, _xlfn._xlws.FILTER( INDIRECT("'"&D$1&"'!A2:E1000"), (INDIRECT("'"&D$1&"'!B2:B1000")=$B7) * (INDIRECT("'"&D$1&"'!C2:C1000")=$C7) ), 5, FALSE )=0, "", VLOOKUP( $A7, _xlfn._xlws.FILTER( INDIRECT("'"&D$1&"'!A2:E1000"), (INDIRECT("'"&D$1&"'!B2:B1000")=$B7) * (INDIRECT("'"&D$1&"'!C2:C1000")=$C7) ), 5, FALSE ) )} | E7: {=IF( VLOOKUP( $A7, _xlfn._xlws.FILTER( INDIRECT("'"&E$1&"'!A2:E1000"), (INDIRECT("'"&E$1&"'!B2:B1000")=$B7) * (INDIRECT("'"&E$1&"'!C2:C1000")=$C7) ), 5, FALSE )=0, "", VLOOKUP( $A7, _xlfn._xlws.FILTER( INDIRECT("'"&E$1&"'!A2:E1000"), (INDIRECT("'"&E$1&"'!B2:B1000")=$B7) * (INDIRECT("'"&E$1&"'!C2:C1000")=$C7) ), 5, FALSE ) )} | F7: {=IF( VLOOKUP( $A7, _xlfn._xlws.FILTER( INDIRECT("'"&F$1&"'!A2:E1000"), (INDIRECT("'"&F$1&"'!B2:B1000")=$B7) * (INDIRECT("'"&F$1&"'!C2:C1000")=$C7) ), 5, FALSE )=0, "", VLOOKUP( $A7, _xlfn._xlws.FILTER( INDIRECT("'"&F$1&"'!A2:E1000"), (INDIRECT("'"&F$1&"'!B2:B1000")=$B7) * (INDIRECT("'"&F$1&"'!C2:C1000")=$C7) ), 5, FALSE ) )}
A8: Bianca | B8: Diamante do Sul | C8: 1 | D8: {=IF( VLOOKUP( $A8, _xlfn._xlws.FILTER( INDIRECT("'"&D$1&"'!A2:E1000"), (INDIRECT("'"&D$1&"'!B2:B1000")=$B8) * (INDIRECT("'"&D$1&"'!C2:C1000")=$C8) ), 5, FALSE )=0, "", VLOOKUP( $A8, _xlfn._xlws.FILTER( INDIRECT("'"&D$1&"'!A2:E1000"), (INDIRECT("'"&D$1&"'!B2:B1000")=$B8) * (INDIRECT("'"&D$1&"'!C2:C1000")=$C8) ), 5, FALSE ) )} | E8: {=IF( VLOOKUP( $A8, _xlfn._xlws.FILTER( INDIRECT("'"&E$1&"'!A2:E1000"), (INDIRECT("'"&E$1&"'!B2:B1000")=$B8) * (INDIRECT("'"&E$1&"'!C2:C1000")=$C8) ), 5, FALSE )=0, "", VLOOKUP( $A8, _xlfn._xlws.FILTER( INDIRECT("'"&E$1&"'!A2:E1000"), (INDIRECT("'"&E$1&"'!B2:B1000")=$B8) * (INDIRECT("'"&E$1&"'!C2:C1000")=$C8) ), 5, FALSE ) )} | F8: {=IF( VLOOKUP( $A8, _xlfn._xlws.FILTER( INDIRECT("'"&F$1&"'!A2:E1000"), (INDIRECT("'"&F$1&"'!B2:B1000")=$B8) * (INDIRECT("'"&F$1&"'!C2:C1000")=$C8) ), 5, FALSE )=0, "", VLOOKUP( $A8, _xlfn._xlws.FILTER( INDIRECT("'"&F$1&"'!A2:E1000"), (INDIRECT("'"&F$1&"'!B2:B1000")=$B8) * (INDIRECT("'"&F$1&"'!C2:C1000")=$C8) ), 5, FALSE ) )}
A9: Bianca | B9: Guaraniacu | C9: 1 | D9: {=IF( VLOOKUP( $A9, _xlfn._xlws.FILTER( INDIRECT("'"&D$1&"'!A2:E1000"), (INDIRECT("'"&D$1&"'!B2:B1000")=$B9) * (INDIRECT("'"&D$1&"'!C2:C1000")=$C9) ), 5, FALSE )=0, "", VLOOKUP( $A9, _xlfn._xlws.FILTER( INDIRECT("'"&D$1&"'!A2:E1000"), (INDIRECT("'"&D$1&"'!B2:B1000")=$B9) * (INDIRECT("'"&D$1&"'!C2:C1000")=$C9) ), 5, FALSE ) )} | E9: {=IF( VLOOKUP( $A9, _xlfn._xlws.FILTER( INDIRECT("'"&E$1&"'!A2:E1000"), (INDIRECT("'"&E$1&"'!B2:B1000")=$B9) * (INDIRECT("'"&E$1&"'!C2:C1000")=$C9) ), 5, FALSE )=0, "", VLOOKUP( $A9, _xlfn._xlws.FILTER( INDIRECT("'"&E$1&"'!A2:E1000"), (INDIRECT("'"&E$1&"'!B2:B1000")=$B9) * (INDIRECT("'"&E$1&"'!C2:C1000")=$C9) ), 5, FALSE ) )} | F9: {=IF( VLOOKUP( $A9, _xlfn._xlws.FILTER( INDIRECT("'"&F$1&"'!A2:E1000"), (INDIRECT("'"&F$1&"'!B2:B1000")=$B9) * (INDIRECT("'"&F$1&"'!C2:C1000")=$C9) ), 5, FALSE )=0, "", VLOOKUP( $A9, _xlfn._xlws.FILTER( INDIRECT("'"&F$1&"'!A2:E1000"), (INDIRECT("'"&F$1&"'!B2:B1000")=$B9) * (INDIRECT("'"&F$1&"'!C2:C1000")=$C9) ), 5, FALSE ) )}
A10: Bianca | B10: Ibema | C10: 1 | D10: {=IF( VLOOKUP( $A10, _xlfn._xlws.FILTER( INDIRECT("'"&D$1&"'!A2:E1000"), (INDIRECT("'"&D$1&"'!B2:B1000")=$B10) * (INDIRECT("'"&D$1&"'!C2:C1000")=$C10) ), 5, FALSE )=0, "", VLOOKUP( $A10, _xlfn._xlws.FILTER( INDIRECT("'"&D$1&"'!A2:E1000"), (INDIRECT("'"&D$1&"'!B2:B1000")=$B10) * (INDIRECT("'"&D$1&"'!C2:C1000")=$C10) ), 5, FALSE ) )} | E10: {=IF( VLOOKUP( $A10, _xlfn._xlws.FILTER( INDIRECT("'"&E$1&"'!A2:E1000"), (INDIRECT("'"&E$1&"'!B2:B1000")=$B10) * (INDIRECT("'"&E$1&"'!C2:C1000")=$C10) ), 5, FALSE )=0, "", VLOOKUP( $A10, _xlfn._xlws.FILTER( INDIRECT("'"&E$1&"'!A2:E1000"), (INDIRECT("'"&E$1&"'!B2:B1000")=$B10) * (INDIRECT("'"&E$1&"'!C2:C1000")=$C10) ), 5, FALSE ) )} | F10: {=IF( VLOOKUP( $A10, _xlfn._xlws.FILTER( INDIRECT("'"&F$1&"'!A2:E1000"), (INDIRECT("'"&F$1&"'!B2:B1000")=$B10) * (INDIRECT("'"&F$1&"'!C2:C1000")=$C10) ), 5, FALSE )=0, "", VLOOKUP( $A10, _xlfn._xlws.FILTER( INDIRECT("'"&F$1&"'!A2:E1000"), (INDIRECT("'"&F$1&"'!B2:B1000")=$B10) * (INDIRECT("'"&F$1&"'!C2:C1000")=$C10) ), 5, FALSE ) )}
A11: Bianca | B11: Iguatu | C11: 1 | D11: {=IF( VLOOKUP( $A11, _xlfn._xlws.FILTER( INDIRECT("'"&D$1&"'!A2:E1000"), (INDIRECT("'"&D$1&"'!B2:B1000")=$B11) * (INDIRECT("'"&D$1&"'!C2:C1000")=$C11) ), 5, FALSE )=0, "", VLOOKUP( $A11, _xlfn._xlws.FILTER( INDIRECT("'"&D$1&"'!A2:E1000"), (INDIRECT("'"&D$1&"'!B2:B1000")=$B11) * (INDIRECT("'"&D$1&"'!C2:C1000")=$C11) ), 5, FALSE ) )} | E11: {=IF( VLOOKUP( $A11, _xlfn._xlws.FILTER( INDIRECT("'"&E$1&"'!A2:E1000"), (INDIRECT("'"&E$1&"'!B2:B1000")=$B11) * (INDIRECT("'"&E$1&"'!C2:C1000")=$C11) ), 5, FALSE )=0, "", VLOOKUP( $A11, _xlfn._xlws.FILTER( INDIRECT("'"&E$1&"'!A2:E1000"), (INDIRECT("'"&E$1&"'!B2:B1000")=$B11) * (INDIRECT("'"&E$1&"'!C2:C1000")=$C11) ), 5, FALSE ) )} | F11: {=IF( VLOOKUP( $A11, _xlfn._xlws.FILTER( INDIRECT("'"&F$1&"'!A2:E1000"), (INDIRECT("'"&F$1&"'!B2:B1000")=$B11) * (INDIRECT("'"&F$1&"'!C2:C1000")=$C11) ), 5, FALSE )=0, "", VLOOKUP( $A11, _xlfn._xlws.FILTER( INDIRECT("'"&F$1&"'!A2:E1000"), (INDIRECT("'"&F$1&"'!B2:B1000")=$B11) * (INDIRECT("'"&F$1&"'!C2:C1000")=$C11) ), 5, FALSE ) )}
A12: Bianca | B12: Tres Barras do Parana | C12: 1 | D12: {=IF( VLOOKUP( $A12, _xlfn._xlws.FILTER( INDIRECT("'"&D$1&"'!A2:E1000"), (INDIRECT("'"&D$1&"'!B2:B1000")=$B12) * (INDIRECT("'"&D$1&"'!C2:C1000")=$C12) ), 5, FALSE )=0, "", VLOOKUP( $A12, _xlfn._xlws.FILTER( INDIRECT("'"&D$1&"'!A2:E1000"), (INDIRECT("'"&D$1&"'!B2:B1000")=$B12) * (INDIRECT("'"&D$1&"'!C2:C1000")=$C12) ), 5, FALSE ) )} | E12: {=IF( VLOOKUP( $A12, _xlfn._xlws.FILTER( INDIRECT("'"&E$1&"'!A2:E1000"), (INDIRECT("'"&E$1&"'!B2:B1000")=$B12) * (INDIRECT("'"&E$1&"'!C2:C1000")=$C12) ), 5, FALSE )=0, "", VLOOKUP( $A12, _xlfn._xlws.FILTER( INDIRECT("'"&E$1&"'!A2:E1000"), (INDIRECT("'"&E$1&"'!B2:B1000")=$B12) * (INDIRECT("'"&E$1&"'!C2:C1000")=$C12) ), 5, FALSE ) )} | F12: {=IF( VLOOKUP( $A12, _xlfn._xlws.FILTER( INDIRECT("'"&F$1&"'!A2:E1000"), (INDIRECT("'"&F$1&"'!B2:B1000")=$B12) * (INDIRECT("'"&F$1&"'!C2:C1000")=$C12) ), 5, FALSE )=0, "", VLOOKUP( $A12, _xlfn._xlws.FILTER( INDIRECT("'"&F$1&"'!A2:E1000"), (INDIRECT("'"&F$1&"'!B2:B1000")=$B12) * (INDIRECT("'"&F$1&"'!C2:C1000")=$C12) ), 5, FALSE ) )}
A14: Regional | B14: Municípios | C14: UVR | D14: Form 1 - Município | E14: Form 2 - UVR | F14: Form 3 - Empreendimento
A15: Gabriel | B15: Altônia | C15: 1 | D15: {=IF( VLOOKUP( $A15, _xlfn._xlws.FILTER( INDIRECT("'"&D$1&"'!A2:E1000"), (INDIRECT("'"&D$1&"'!B2:B1000")=$B15) * (INDIRECT("'"&D$1&"'!C2:C1000")=$C15) ), 5, FALSE )=0, "", VLOOKUP( $A15, _xlfn._xlws.FILTER( INDIRECT("'"&D$1&"'!A2:E1000"), (INDIRECT("'"&D$1&"'!B2:B1000")=$B15) * (INDIRECT("'"&D$1&"'!C2:C1000")=$C15) ), 5, FALSE ) )} | E15: {=IF( VLOOKUP( $A15, _xlfn._xlws.FILTER( INDIRECT("'"&E$1&"'!A2:E1000"), (INDIRECT("'"&E$1&"'!B2:B1000")=$B15) * (INDIRECT("'"&E$1&"'!C2:C1000")=$C15) ), 5, FALSE )=0, "", VLOOKUP( $A15, _xlfn._xlws.FILTER( INDIRECT("'"&E$1&"'!A2:E1000"), (INDIRECT("'"&E$1&"'!B2:B1000")=$B15) * (INDIRECT("'"&E$1&"'!C2:C1000")=$C15) ), 5, FALSE ) )} | F15: {=IF( VLOOKUP( $A15, _xlfn._xlws.FILTER( INDIRECT("'"&F$1&"'!A2:E1000"), (INDIRECT("'"&F$1&"'!B2:B1000")=$B15) * (INDIRECT("'"&F$1&"'!C2:C1000")=$C15) ), 5, FALSE )=0, "", VLOOKUP( $A15, _xlfn._xlws.FILTER( INDIRECT("'"&F$1&"'!A2:E1000"), (INDIRECT("'"&F$1&"'!B2:B1000")=$B15) * (INDIRECT("'"&F$1&"'!C2:C1000")=$C15) ), 5, FALSE ) )}
A16: Gabriel | B16: Francisco Alves | C16: 1 | D16: {=IF( VLOOKUP( $A16, _xlfn._xlws.FILTER( INDIRECT("'"&D$1&"'!A2:E1000"), (INDIRECT("'"&D$1&"'!B2:B1000")=$B16) * (INDIRECT("'"&D$1&"'!C2:C1000")=$C16) ), 5, FALSE )=0, "", VLOOKUP( $A16, _xlfn._xlws.FILTER( INDIRECT("'"&D$1&"'!A2:E1000"), (INDIRECT("'"&D$1&"'!B2:B1000")=$B16) * (INDIRECT("'"&D$1&"'!C2:C1000")=$C16) ), 5, FALSE ) )} | E16: {=IF( VLOOKUP( $A16, _xlfn._xlws.FILTER( INDIRECT("'"&E$1&"'!A2:E1000"), (INDIRECT("'"&E$1&"'!B2:B1000")=$B16) * (INDIRECT("'"&E$1&"'!C2:C1000")=$C16) ), 5, FALSE )=0, "", VLOOKUP( $A16, _xlfn._xlws.FILTER( INDIRECT("'"&E$1&"'!A2:E1000"), (INDIRECT("'"&E$1&"'!B2:B1000")=$B16) * (INDIRECT("'"&E$1&"'!C2:C1000")=$C16) ), 5, FALSE ) )} | F16: {=IF( VLOOKUP( $A16, _xlfn._xlws.FILTER( INDIRECT("'"&F$1&"'!A2:E1000"), (INDIRECT("'"&F$1&"'!B2:B1000")=$B16) * (INDIRECT("'"&F$1&"'!C2:C1000")=$C16) ), 5, FALSE )=0, "", VLOOKUP( $A16, _xlfn._xlws.FILTER( INDIRECT("'"&F$1&"'!A2:E1000"), (INDIRECT("'"&F$1&"'!B2:B1000")=$B16) * (INDIRECT("'"&F$1&"'!C2:C1000")=$C16) ), 5, FALSE ) )}
A17: Gabriel | B17: Guaira | C17: 1 | D17: {=IF( VLOOKUP( $A17, _xlfn._xlws.FILTER( INDIRECT("'"&D$1&"'!A2:E1000"), (INDIRECT("'"&D$1&"'!B2:B1000")=$B17) * (INDIRECT("'"&D$1&"'!C2:C1000")=$C17) ), 5, FALSE )=0, "", VLOOKUP( $A17, _xlfn._xlws.FILTER( INDIRECT("'"&D$1&"'!A2:E1000"), (INDIRECT("'"&D$1&"'!B2:B1000")=$B17) * (INDIRECT("'"&D$1&"'!C2:C1000")=$C17) ), 5, FALSE ) )} | E17: {=IF( VLOOKUP( $A17, _xlfn._xlws.FILTER( INDIRECT("'"&E$1&"'!A2:E1000"), (INDIRECT("'"&E$1&"'!B2:B1000")=$B17) * (INDIRECT("'"&E$1&"'!C2:C1000")=$C17) ), 5, FALSE )=0, "", VLOOKUP( $A17, _xlfn._xlws.FILTER( INDIRECT("'"&E$1&"'!A2:E1000"), (INDIRECT("'"&E$1&"'!B2:B1000")=$B17) * (INDIRECT("'"&E$1&"'!C2:C1000")=$C17) ), 5, FALSE ) )} | F17: {=IF( VLOOKUP( $A17, _xlfn._xlws.FILTER( INDIRECT("'"&F$1&"'!A2:E1000"), (INDIRECT("'"&F$1&"'!B2:B1000")=$B17) * (INDIRECT("'"&F$1&"'!C2:C1000")=$C17) ), 5, FALSE )=0, "", VLOOKUP( $A17, _xlfn._xlws.FILTER( INDIRECT("'"&F$1&"'!A2:E1000"), (INDIRECT("'"&F$1&"'!B2:B1000")=$B17) * (INDIRECT("'"&F$1&"'!C2:C1000")=$C17) ), 5, FALSE ) )}
A18: Gabriel | B18: Mercedes | C18: 1 | D18: {=IF( VLOOKUP( $A18, _xlfn._xlws.FILTER( INDIRECT("'"&D$1&"'!A2:E1000"), (INDIRECT("'"&D$1&"'!B2:B1000")=$B18) * (INDIRECT("'"&D$1&"'!C2:C1000")=$C18) ), 5, FALSE )=0, "", VLOOKUP( $A18, _xlfn._xlws.FILTER( INDIRECT("'"&D$1&"'!A2:E1000"), (INDIRECT("'"&D$1&"'!B2:B1000")=$B18) * (INDIRECT("'"&D$1&"'!C2:C1000")=$C18) ), 5, FALSE ) )} | E18: {=IF( VLOOKUP( $A18, _xlfn._xlws.FILTER( INDIRECT("'"&E$1&"'!A2:E1000"), (INDIRECT("'"&E$1&"'!B2:B1000")=$B18) * (INDIRECT("'"&E$1&"'!C2:C1000")=$C18) ), 5, FALSE )=0, "", VLOOKUP( $A18, _xlfn._xlws.FILTER( INDIRECT("'"&E$1&"'!A2:E1000"), (INDIRECT("'"&E$1&"'!B2:B1000")=$B18) * (INDIRECT("'"&E$1&"'!C2:C1000")=$C18) ), 5, FALSE ) )} | F18: {=IF( VLOOKUP( $A18, _xlfn._xlws.FILTER( INDIRECT("'"&F$1&"'!A2:E1000"), (INDIRECT("'"&F$1&"'!B2:B1000")=$B18) * (INDIRECT("'"&F$1&"'!C2:C1000")=$C18) ), 5, FALSE )=0, "", VLOOKUP( $A18, _xlfn._xlws.FILTER( INDIRECT("'"&F$1&"'!A2:E1000"), (INDIRECT("'"&F$1&"'!B2:B1000")=$B18) * (INDIRECT("'"&F$1&"'!C2:C1000")=$C18) ), 5, FALSE ) )}
A19: Gabriel | B19: Mundo Novo | C19: 1 | D19: {=IF( VLOOKUP( $A19, _xlfn._xlws.FILTER( INDIRECT("'"&D$1&"'!A2:E1000"), (INDIRECT("'"&D$1&"'!B2:B1000")=$B19) * (INDIRECT("'"&D$1&"'!C2:C1000")=$C19) ), 5, FALSE )=0, "", VLOOKUP( $A19, _xlfn._xlws.FILTER( INDIRECT("'"&D$1&"'!A2:E1000"), (INDIRECT("'"&D$1&"'!B2:B1000")=$B19) * (INDIRECT("'"&D$1&"'!C2:C1000")=$C19) ), 5, FALSE ) )} | E19: {=IF( VLOOKUP( $A19, _xlfn._xlws.FILTER( INDIRECT("'"&E$1&"'!A2:E1000"), (INDIRECT("'"&E$1&"'!B2:B1000")=$B19) * (INDIRECT("'"&E$1&"'!C2:C1000")=$C19) ), 5, FALSE )=0, "", VLOOKUP( $A19, _xlfn._xlws.FILTER( INDIRECT("'"&E$1&"'!A2:E1000"), (INDIRECT("'"&E$1&"'!B2:B1000")=$B19) * (INDIRECT("'"&E$1&"'!C2:C1000")=$C19) ), 5, FALSE ) )} | F19: {=IF( VLOOKUP( $A19, _xlfn._xlws.FILTER( INDIRECT("'"&F$1&"'!A2:E1000"), (INDIRECT("'"&F$1&"'!B2:B1000")=$B19) * (INDIRECT("'"&F$1&"'!C2:C1000")=$C19) ), 5, FALSE )=0, "", VLOOKUP( $A19, _xlfn._xlws.FILTER( INDIRECT("'"&F$1&"'!A2:E1000"), (INDIRECT("'"&F$1&"'!B2:B1000")=$B19) * (INDIRECT("'"&F$1&"'!C2:C1000")=$C19) ), 5, FALSE ) )}
A20: Gabriel | B20: Nova Santa Rosa | C20: 1 | D20: {=IF( VLOOKUP( $A20, _xlfn._xlws.FILTER( INDIRECT("'"&D$1&"'!A2:E1000"), (INDIRECT("'"&D$1&"'!B2:B1000")=$B20) * (INDIRECT("'"&D$1&"'!C2:C1000")=$C20) ), 5, FALSE )=0, "", VLOOKUP( $A20, _xlfn._xlws.FILTER( INDIRECT("'"&D$1&"'!A2:E1000"), (INDIRECT("'"&D$1&"'!B2:B1000")=$B20) * (INDIRECT("'"&D$1&"'!C2:C1000")=$C20) ), 5, FALSE ) )} | E20: {=IF( VLOOKUP( $A20, _xlfn._xlws.FILTER( INDIRECT("'"&E$1&"'!A2:E1000"), (INDIRECT("'"&E$1&"'!B2:B1000")=$B20) * (INDIRECT("'"&E$1&"'!C2:C1000")=$C20) ), 5, FALSE )=0, "", VLOOKUP( $A20, _xlfn._xlws.FILTER( INDIRECT("'"&E$1&"'!A2:E1000"), (INDIRECT("'"&E$1&"'!B2:B1000")=$B20) * (INDIRECT("'"&E$1&"'!C2:C1000")=$C20) ), 5, FALSE ) )} | F20: {=IF( VLOOKUP( $A20, _xlfn._xlws.FILTER( INDIRECT("'"&F$1&"'!A2:E1000"), (INDIRECT("'"&F$1&"'!B2:B1000")=$B20) * (INDIRECT("'"&F$1&"'!C2:C1000")=$C20) ), 5, FALSE )=0, "", VLOOKUP( $A20, _xlfn._xlws.FILTER( INDIRECT("'"&F$1&"'!A2:E1000"), (INDIRECT("'"&F$1&"'!B2:B1000")=$B20) * (INDIRECT("'"&F$1&"'!C2:C1000")=$C20) ), 5, FALSE ) )}
A21: Gabriel | B21: Ouro Verde do Oeste | C21: 1 | D21: {=IF( VLOOKUP( $A21, _xlfn._xlws.FILTER( INDIRECT("'"&D$1&"'!A2:E1000"), (INDIRECT("'"&D$1&"'!B2:B1000")=$B21) * (INDIRECT("'"&D$1&"'!C2:C1000")=$C21) ), 5, FALSE )=0, "", VLOOKUP( $A21, _xlfn._xlws.FILTER( INDIRECT("'"&D$1&"'!A2:E1000"), (INDIRECT("'"&D$1&"'!B2:B1000")=$B21) * (INDIRECT("'"&D$1&"'!C2:C1000")=$C21) ), 5, FALSE ) )} | E21: {=IF( VLOOKUP( $A21, _xlfn._xlws.FILTER( INDIRECT("'"&E$1&"'!A2:E1000"), (INDIRECT("'"&E$1&"'!B2:B1000")=$B21) * (INDIRECT("'"&E$1&"'!C2:C1000")=$C21) ), 5, FALSE )=0, "", VLOOKUP( $A21, _xlfn._xlws.FILTER( INDIRECT("'"&E$1&"'!A2:E1000"), (INDIRECT("'"&E$1&"'!B2:B1000")=$B21) * (INDIRECT("'"&E$1&"'!C2:C1000")=$C21) ), 5, FALSE ) )} | F21: {=IF( VLOOKUP( $A21, _xlfn._xlws.FILTER( INDIRECT("'"&F$1&"'!A2:E1000"), (INDIRECT("'"&F$1&"'!B2:B1000")=$B21) * (INDIRECT("'"&F$1&"'!C2:C1000")=$C21) ), 5, FALSE )=0, "", VLOOKUP( $A21, _xlfn._xlws.FILTER( INDIRECT("'"&F$1&"'!A2:E1000"), (INDIRECT("'"&F$1&"'!B2:B1000")=$B21) * (INDIRECT("'"&F$1&"'!C2:C1000")=$C21) ), 5, FALSE ) )}
A22: Gabriel | B22: Quatro Pontes | C22: 1 | D22: {=IF( VLOOKUP( $A22, _xlfn._xlws.FILTER( INDIRECT("'"&D$1&"'!A2:E1000"), (INDIRECT("'"&D$1&"'!B2:B1000")=$B22) * (INDIRECT("'"&D$1&"'!C2:C1000")=$C22) ), 5, FALSE )=0, "", VLOOKUP( $A22, _xlfn._xlws.FILTER( INDIRECT("'"&D$1&"'!A2:E1000"), (INDIRECT("'"&D$1&"'!B2:B1000")=$B22) * (INDIRECT("'"&D$1&"'!C2:C1000")=$C22) ), 5, FALSE ) )} | E22: {=IF( VLOOKUP( $A22, _xlfn._xlws.FILTER( INDIRECT("'"&E$1&"'!A2:E1000"), (INDIRECT("'"&E$1&"'!B2:B1000")=$B22) * (INDIRECT("'"&E$1&"'!C2:C1000")=$C22) ), 5, FALSE )=0, "", VLOOKUP( $A22, _xlfn._xlws.FILTER( INDIRECT("'"&E$1&"'!A2:E1000"), (INDIRECT("'"&E$1&"'!B2:B1000")=$B22) * (INDIRECT("'"&E$1&"'!C2:C1000")=$C22) ), 5, FALSE ) )} | F22: {=IF( VLOOKUP( $A22, _xlfn._xlws.FILTER( INDIRECT("'"&F$1&"'!A2:E1000"), (INDIRECT("'"&F$1&"'!B2:B1000")=$B22) * (INDIRECT("'"&F$1&"'!C2:C1000")=$C22) ), 5, FALSE )=0, "", VLOOKUP( $A22, _xlfn._xlws.FILTER( INDIRECT("'"&F$1&"'!A2:E1000"), (INDIRECT("'"&F$1&"'!B2:B1000")=$B22) * (INDIRECT("'"&F$1&"'!C2:C1000")=$C22) ), 5, FALSE ) )}
A23: Gabriel | B23: São Jose das Palmeiras | C23: 1 | D23: {=IF( VLOOKUP( $A23, _xlfn._xlws.FILTER( INDIRECT("'"&D$1&"'!A2:E1000"), (INDIRECT("'"&D$1&"'!B2:B1000")=$B23) * (INDIRECT("'"&D$1&"'!C2:C1000")=$C23) ), 5, FALSE )=0, "", VLOOKUP( $A23, _xlfn._xlws.FILTER( INDIRECT("'"&D$1&"'!A2:E1000"), (INDIRECT("'"&D$1&"'!B2:B1000")=$B23) * (INDIRECT("'"&D$1&"'!C2:C1000")=$C23) ), 5, FALSE ) )} | E23: {=IF( VLOOKUP( $A23, _xlfn._xlws.FILTER( INDIRECT("'"&E$1&"'!A2:E1000"), (INDIRECT("'"&E$1&"'!B2:B1000")=$B23) * (INDIRECT("'"&E$1&"'!C2:C1000")=$C23) ), 5, FALSE )=0, "", VLOOKUP( $A23, _xlfn._xlws.FILTER( INDIRECT("'"&E$1&"'!A2:E1000"), (INDIRECT("'"&E$1&"'!B2:B1000")=$B23) * (INDIRECT("'"&E$1&"'!C2:C1000")=$C23) ), 5, FALSE ) )} | F23: {=IF( VLOOKUP( $A23, _xlfn._xlws.FILTER( INDIRECT("'"&F$1&"'!A2:E1000"), (INDIRECT("'"&F$1&"'!B2:B1000")=$B23) * (INDIRECT("'"&F$1&"'!C2:C1000")=$C23) ), 5, FALSE )=0, "", VLOOKUP( $A23, _xlfn._xlws.FILTER( INDIRECT("'"&F$1&"'!A2:E1000"), (INDIRECT("'"&F$1&"'!B2:B1000")=$B23) * (INDIRECT("'"&F$1&"'!C2:C1000")=$C23) ), 5, FALSE ) )}
A24: Gabriel | B24: Terra Roxa | C24: 1 | D24: {=IF( VLOOKUP( $A24, _xlfn._xlws.FILTER( INDIRECT("'"&D$1&"'!A2:E1000"), (INDIRECT("'"&D$1&"'!B2:B1000")=$B24) * (INDIRECT("'"&D$1&"'!C2:C1000")=$C24) ), 5, FALSE )=0, "", VLOOKUP( $A24, _xlfn._xlws.FILTER( INDIRECT("'"&D$1&"'!A2:E1000"), (INDIRECT("'"&D$1&"'!B2:B1000")=$B24) * (INDIRECT("'"&D$1&"'!C2:C1000")=$C24) ), 5, FALSE ) )} | E24: {=IF( VLOOKUP( $A24, _xlfn._xlws.FILTER( INDIRECT("'"&E$1&"'!A2:E1000"), (INDIRECT("'"&E$1&"'!B2:B1000")=$B24) * (INDIRECT("'"&E$1&"'!C2:C1000")=$C24) ), 5, FALSE )=0, "", VLOOKUP( $A24, _xlfn._xlws.FILTER( INDIRECT("'"&E$1&"'!A2:E1000"), (INDIRECT("'"&E$1&"'!B2:B1000")=$B24) * (INDIRECT("'"&E$1&"'!C2:C1000")=$C24) ), 5, FALSE ) )} | F24: {=IF( VLOOKUP( $A24, _xlfn._xlws.FILTER( INDIRECT("'"&F$1&"'!A2:E1000"), (INDIRECT("'"&F$1&"'!B2:B1000")=$B24) * (INDIRECT("'"&F$1&"'!C2:C1000")=$C24) ), 5, FALSE )=0, "", VLOOKUP( $A24, _xlfn._xlws.FILTER( INDIRECT("'"&F$1&"'!A2:E1000"), (INDIRECT("'"&F$1&"'!B2:B1000")=$B24) * (INDIRECT("'"&F$1&"'!C2:C1000")=$C24) ), 5, FALSE ) )}
A25: Gabriel | B25: Toledo | C25: 1 | D25: {=IF( VLOOKUP( $A25, _xlfn._xlws.FILTER( INDIRECT("'"&D$1&"'!A2:E1000"), (INDIRECT("'"&D$1&"'!B2:B1000")=$B25) * (INDIRECT("'"&D$1&"'!C2:C1000")=$C25) ), 5, FALSE )=0, "", VLOOKUP( $A25, _xlfn._xlws.FILTER( INDIRECT("'"&D$1&"'!A2:E1000"), (INDIRECT("'"&D$1&"'!B2:B1000")=$B25) * (INDIRECT("'"&D$1&"'!C2:C1000")=$C25) ), 5, FALSE ) )} | E25: {=IF( VLOOKUP( $A25, _xlfn._xlws.FILTER( INDIRECT("'"&E$1&"'!A2:E1000"), (INDIRECT("'"&E$1&"'!B2:B1000")=$B25) * (INDIRECT("'"&E$1&"'!C2:C1000")=$C25) ), 5, FALSE )=0, "", VLOOKUP( $A25, _xlfn._xlws.FILTER( INDIRECT("'"&E$1&"'!A2:E1000"), (INDIRECT("'"&E$1&"'!B2:B1000")=$B25) * (INDIRECT("'"&E$1&"'!C2:C1000")=$C25) ), 5, FALSE ) )} | F25: {=IF( VLOOKUP( $A25, _xlfn._xlws.FILTER( INDIRECT("'"&F$1&"'!A2:E1000"), (INDIRECT("'"&F$1&"'!B2:B1000")=$B25) * (INDIRECT("'"&F$1&"'!C2:C1000")=$C25) ), 5, FALSE )=0, "", VLOOKUP( $A25, _xlfn._xlws.FILTER( INDIRECT("'"&F$1&"'!A2:E1000"), (INDIRECT("'"&F$1&"'!B2:B1000")=$B25) * (INDIRECT("'"&F$1&"'!C2:C1000")=$C25) ), 5, FALSE ) )}
A27: Regional | B27: Municípios | C27: UVR | D27: Form 1 - Município | E27: Form 2 - UVR | F27: Form 3 - Empreendimento
A28: Gustavo | B28: Assis Chateaubriand | C28: 1 | D28: {=IF( VLOOKUP( $A28, _xlfn._xlws.FILTER( INDIRECT("'"&D$1&"'!A2:E1000"), (INDIRECT("'"&D$1&"'!B2:B1000")=$B28) * (INDIRECT("'"&D$1&"'!C2:C1000")=$C28) ), 5, FALSE )=0, "", VLOOKUP( $A28, _xlfn._xlws.FILTER( INDIRECT("'"&D$1&"'!A2:E1000"), (INDIRECT("'"&D$1&"'!B2:B1000")=$B28) * (INDIRECT("'"&D$1&"'!C2:C1000")=$C28) ), 5, FALSE ) )} | E28: {=IF( VLOOKUP( $A28, _xlfn._xlws.FILTER( INDIRECT("'"&E$1&"'!A2:E1000"), (INDIRECT("'"&E$1&"'!B2:B1000")=$B28) * (INDIRECT("'"&E$1&"'!C2:C1000")=$C28) ), 5, FALSE )=0, "", VLOOKUP( $A28, _xlfn._xlws.FILTER( INDIRECT("'"&E$1&"'!A2:E1000"), (INDIRECT("'"&E$1&"'!B2:B1000")=$B28) * (INDIRECT("'"&E$1&"'!C2:C1000")=$C28) ), 5, FALSE ) )} | F28: {=IF( VLOOKUP( $A28, _xlfn._xlws.FILTER( INDIRECT("'"&F$1&"'!A2:E1000"), (INDIRECT("'"&F$1&"'!B2:B1000")=$B28) * (INDIRECT("'"&F$1&"'!C2:C1000")=$C28) ), 5, FALSE )=0, "", VLOOKUP( $A28, _xlfn._xlws.FILTER( INDIRECT("'"&F$1&"'!A2:E1000"), (INDIRECT("'"&F$1&"'!B2:B1000")=$B28) * (INDIRECT("'"&F$1&"'!C2:C1000")=$C28) ), 5, FALSE ) )}
A29: Gustavo | B29: Brasilândia do Sul | C29: 1 | D29: {=IF( VLOOKUP( $A29, _xlfn._xlws.FILTER( INDIRECT("'"&D$1&"'!A2:E1000"), (INDIRECT("'"&D$1&"'!B2:B1000")=$B29) * (INDIRECT("'"&D$1&"'!C2:C1000")=$C29) ), 5, FALSE )=0, "", VLOOKUP( $A29, _xlfn._xlws.FILTER( INDIRECT("'"&D$1&"'!A2:E1000"), (INDIRECT("'"&D$1&"'!B2:B1000")=$B29) * (INDIRECT("'"&D$1&"'!C2:C1000")=$C29) ), 5, FALSE ) )} | E29: {=IF( VLOOKUP( $A29, _xlfn._xlws.FILTER( INDIRECT("'"&E$1&"'!A2:E1000"), (INDIRECT("'"&E$1&"'!B2:B1000")=$B29) * (INDIRECT("'"&E$1&"'!C2:C1000")=$C29) ), 5, FALSE )=0, "", VLOOKUP( $A29, _xlfn._xlws.FILTER( INDIRECT("'"&E$1&"'!A2:E1000"), (INDIRECT("'"&E$1&"'!B2:B1000")=$B29) * (INDIRECT("'"&E$1&"'!C2:C1000")=$C29) ), 5, FALSE ) )} | F29: {=IF( VLOOKUP( $A29, _xlfn._xlws.FILTER( INDIRECT("'"&F$1&"'!A2:E1000"), (INDIRECT("'"&F$1&"'!B2:B1000")=$B29) * (INDIRECT("'"&F$1&"'!C2:C1000")=$C29) ), 5, FALSE )=0, "", VLOOKUP( $A29, _xlfn._xlws.FILTER( INDIRECT("'"&F$1&"'!A2:E1000"), (INDIRECT("'"&F$1&"'!B2:B1000")=$B29) * (INDIRECT("'"&F$1&"'!C2:C1000")=$C29) ), 5, FALSE ) )}
A30: Gustavo | B30: Cafelândia | C30: 1 | D30: {=IF( VLOOKUP( $A30, _xlfn._xlws.FILTER( INDIRECT("'"&D$1&"'!A2:E1000"), (INDIRECT("'"&D$1&"'!B2:B1000")=$B30) * (INDIRECT("'"&D$1&"'!C2:C1000")=$C30) ), 5, FALSE )=0, "", VLOOKUP( $A30, _xlfn._xlws.FILTER( INDIRECT("'"&D$1&"'!A2:E1000"), (INDIRECT("'"&D$1&"'!B2:B1000")=$B30) * (INDIRECT("'"&D$1&"'!C2:C1000")=$C30) ), 5, FALSE ) )} | E30: {=IF( VLOOKUP( $A30, _xlfn._xlws.FILTER( INDIRECT("'"&E$1&"'!A2:E1000"), (INDIRECT("'"&E$1&"'!B2:B1000")=$B30) * (INDIRECT("'"&E$1&"'!C2:C1000")=$C30) ), 5, FALSE )=0, "", VLOOKUP( $A30, _xlfn._xlws.FILTER( INDIRECT("'"&E$1&"'!A2:E1000"), (INDIRECT("'"&E$1&"'!B2:B1000")=$B30) * (INDIRECT("'"&E$1&"'!C2:C1000")=$C30) ), 5, FALSE ) )} | F30: {=IF( VLOOKUP( $A30, _xlfn._xlws.FILTER( INDIRECT("'"&F$1&"'!A2:E1000"), (INDIRECT("'"&F$1&"'!B2:B1000")=$B30) * (INDIRECT("'"&F$1&"'!C2:C1000")=$C30) ), 5, FALSE )=0, "", VLOOKUP( $A30, _xlfn._xlws.FILTER( INDIRECT("'"&F$1&"'!A2:E1000"), (INDIRECT("'"&F$1&"'!B2:B1000")=$B30) * (INDIRECT("'"&F$1&"'!C2:C1000")=$C30) ), 5, FALSE ) )}
A31: Gustavo | B31: Formosa do Oeste | C31: 1 | D31: {=IF( VLOOKUP( $A31, _xlfn._xlws.FILTER( INDIRECT("'"&D$1&"'!A2:E1000"), (INDIRECT("'"&D$1&"'!B2:B1000")=$B31) * (INDIRECT("'"&D$1&"'!C2:C1000")=$C31) ), 5, FALSE )=0, "", VLOOKUP( $A31, _xlfn._xlws.FILTER( INDIRECT("'"&D$1&"'!A2:E1000"), (INDIRECT("'"&D$1&"'!B2:B1000")=$B31) * (INDIRECT("'"&D$1&"'!C2:C1000")=$C31) ), 5, FALSE ) )} | E31: {=IF( VLOOKUP( $A31, _xlfn._xlws.FILTER( INDIRECT("'"&E$1&"'!A2:E1000"), (INDIRECT("'"&E$1&"'!B2:B1000")=$B31) * (INDIRECT("'"&E$1&"'!C2:C1000")=$C31) ), 5, FALSE )=0, "", VLOOKUP( $A31, _xlfn._xlws.FILTER( INDIRECT("'"&E$1&"'!A2:E1000"), (INDIRECT("'"&E$1&"'!B2:B1000")=$B31) * (INDIRECT("'"&E$1&"'!C2:C1000")=$C31) ), 5, FALSE ) )} | F31: {=IF( VLOOKUP( $A31, _xlfn._xlws.FILTER( INDIRECT("'"&F$1&"'!A2:E1000"), (INDIRECT("'"&F$1&"'!B2:B1000")=$B31) * (INDIRECT("'"&F$1&"'!C2:C1000")=$C31) ), 5, FALSE )=0, "", VLOOKUP( $A31, _xlfn._xlws.FILTER( INDIRECT("'"&F$1&"'!A2:E1000"), (INDIRECT("'"&F$1&"'!B2:B1000")=$B31) * (INDIRECT("'"&F$1&"'!C2:C1000")=$C31) ), 5, FALSE ) )}
A32: Gustavo | B32: Iracema do Oeste | C32: 1 | D32: {=IF( VLOOKUP( $A32, _xlfn._xlws.FILTER( INDIRECT("'"&D$1&"'!A2:E1000"), (INDIRECT("'"&D$1&"'!B2:B1000")=$B32) * (INDIRECT("'"&D$1&"'!C2:C1000")=$C32) ), 5, FALSE )=0, "", VLOOKUP( $A32, _xlfn._xlws.FILTER( INDIRECT("'"&D$1&"'!A2:E1000"), (INDIRECT("'"&D$1&"'!B2:B1000")=$B32) * (INDIRECT("'"&D$1&"'!C2:C1000")=$C32) ), 5, FALSE ) )} | E32: {=IF( VLOOKUP( $A32, _xlfn._xlws.FILTER( INDIRECT("'"&E$1&"'!A2:E1000"), (INDIRECT("'"&E$1&"'!B2:B1000")=$B32) * (INDIRECT("'"&E$1&"'!C2:C1000")=$C32) ), 5, FALSE )=0, "", VLOOKUP( $A32, _xlfn._xlws.FILTER( INDIRECT("'"&E$1&"'!A2:E1000"), (INDIRECT("'"&E$1&"'!B2:B1000")=$B32) * (INDIRECT("'"&E$1&"'!C2:C1000")=$C32) ), 5, FALSE ) )} | F32: {=IF( VLOOKUP( $A32, _xlfn._xlws.FILTER( INDIRECT("'"&F$1&"'!A2:E1000"), (INDIRECT("'"&F$1&"'!B2:B1000")=$B32) * (INDIRECT("'"&F$1&"'!C2:C1000")=$C32) ), 5, FALSE )=0, "", VLOOKUP( $A32, _xlfn._xlws.FILTER( INDIRECT("'"&F$1&"'!A2:E1000"), (INDIRECT("'"&F$1&"'!B2:B1000")=$B32) * (INDIRECT("'"&F$1&"'!C2:C1000")=$C32) ), 5, FALSE ) )}
A33: Gustavo | B33: Jesuítas | C33: 1 | D33: {=IF( VLOOKUP( $A33, _xlfn._xlws.FILTER( INDIRECT("'"&D$1&"'!A2:E1000"), (INDIRECT("'"&D$1&"'!B2:B1000")=$B33) * (INDIRECT("'"&D$1&"'!C2:C1000")=$C33) ), 5, FALSE )=0, "", VLOOKUP( $A33, _xlfn._xlws.FILTER( INDIRECT("'"&D$1&"'!A2:E1000"), (INDIRECT("'"&D$1&"'!B2:B1000")=$B33) * (INDIRECT("'"&D$1&"'!C2:C1000")=$C33) ), 5, FALSE ) )} | E33: {=IF( VLOOKUP( $A33, _xlfn._xlws.FILTER( INDIRECT("'"&E$1&"'!A2:E1000"), (INDIRECT("'"&E$1&"'!B2:B1000")=$B33) * (INDIRECT("'"&E$1&"'!C2:C1000")=$C33) ), 5, FALSE )=0, "", VLOOKUP( $A33, _xlfn._xlws.FILTER( INDIRECT("'"&E$1&"'!A2:E1000"), (INDIRECT("'"&E$1&"'!B2:B1000")=$B33) * (INDIRECT("'"&E$1&"'!C2:C1000")=$C33) ), 5, FALSE ) )} | F33: {=IF( VLOOKUP( $A33, _xlfn._xlws.FILTER( INDIRECT("'"&F$1&"'!A2:E1000"), (INDIRECT("'"&F$1&"'!B2:B1000")=$B33) * (INDIRECT("'"&F$1&"'!C2:C1000")=$C33) ), 5, FALSE )=0, "", VLOOKUP( $A33, _xlfn._xlws.FILTER( INDIRECT("'"&F$1&"'!A2:E1000"), (INDIRECT("'"&F$1&"'!B2:B1000")=$B33) * (INDIRECT("'"&F$1&"'!C2:C1000")=$C33) ), 5, FALSE ) )}
A34: Gustavo | B34: Maripa | C34: 1 | D34: {=IF( VLOOKUP( $A34, _xlfn._xlws.FILTER( INDIRECT("'"&D$1&"'!A2:E1000"), (INDIRECT("'"&D$1&"'!B2:B1000")=$B34) * (INDIRECT("'"&D$1&"'!C2:C1000")=$C34) ), 5, FALSE )=0, "", VLOOKUP( $A34, _xlfn._xlws.FILTER( INDIRECT("'"&D$1&"'!A2:E1000"), (INDIRECT("'"&D$1&"'!B2:B1000")=$B34) * (INDIRECT("'"&D$1&"'!C2:C1000")=$C34) ), 5, FALSE ) )} | E34: {=IF( VLOOKUP( $A34, _xlfn._xlws.FILTER( INDIRECT("'"&E$1&"'!A2:E1000"), (INDIRECT("'"&E$1&"'!B2:B1000")=$B34) * (INDIRECT("'"&E$1&"'!C2:C1000")=$C34) ), 5, FALSE )=0, "", VLOOKUP( $A34, _xlfn._xlws.FILTER( INDIRECT("'"&E$1&"'!A2:E1000"), (INDIRECT("'"&E$1&"'!B2:B1000")=$B34) * (INDIRECT("'"&E$1&"'!C2:C1000")=$C34) ), 5, FALSE ) )} | F34: {=IF( VLOOKUP( $A34, _xlfn._xlws.FILTER( INDIRECT("'"&F$1&"'!A2:E1000"), (INDIRECT("'"&F$1&"'!B2:B1000")=$B34) * (INDIRECT("'"&F$1&"'!C2:C1000")=$C34) ), 5, FALSE )=0, "", VLOOKUP( $A34, _xlfn._xlws.FILTER( INDIRECT("'"&F$1&"'!A2:E1000"), (INDIRECT("'"&F$1&"'!B2:B1000")=$B34) * (INDIRECT("'"&F$1&"'!C2:C1000")=$C34) ), 5, FALSE ) )}
A35: Gustavo | B35: Nova Aurora | C35: 1 | D35: {=IF( VLOOKUP( $A35, _xlfn._xlws.FILTER( INDIRECT("'"&D$1&"'!A2:E1000"), (INDIRECT("'"&D$1&"'!B2:B1000")=$B35) * (INDIRECT("'"&D$1&"'!C2:C1000")=$C35) ), 5, FALSE )=0, "", VLOOKUP( $A35, _xlfn._xlws.FILTER( INDIRECT("'"&D$1&"'!A2:E1000"), (INDIRECT("'"&D$1&"'!B2:B1000")=$B35) * (INDIRECT("'"&D$1&"'!C2:C1000")=$C35) ), 5, FALSE ) )} | E35: {=IF( VLOOKUP( $A35, _xlfn._xlws.FILTER( INDIRECT("'"&E$1&"'!A2:E1000"), (INDIRECT("'"&E$1&"'!B2:B1000")=$B35) * (INDIRECT("'"&E$1&"'!C2:C1000")=$C35) ), 5, FALSE )=0, "", VLOOKUP( $A35, _xlfn._xlws.FILTER( INDIRECT("'"&E$1&"'!A2:E1000"), (INDIRECT("'"&E$1&"'!B2:B1000")=$B35) * (INDIRECT("'"&E$1&"'!C2:C1000")=$C35) ), 5, FALSE ) )} | F35: {=IF( VLOOKUP( $A35, _xlfn._xlws.FILTER( INDIRECT("'"&F$1&"'!A2:E1000"), (INDIRECT("'"&F$1&"'!B2:B1000")=$B35) * (INDIRECT("'"&F$1&"'!C2:C1000")=$C35) ), 5, FALSE )=0, "", VLOOKUP( $A35, _xlfn._xlws.FILTER( INDIRECT("'"&F$1&"'!A2:E1000"), (INDIRECT("'"&F$1&"'!B2:B1000")=$B35) * (INDIRECT("'"&F$1&"'!C2:C1000")=$C35) ), 5, FALSE ) )}
A36: Gustavo | B36: Palotina | C36: 1 | D36: {=IF( VLOOKUP( $A36, _xlfn._xlws.FILTER( INDIRECT("'"&D$1&"'!A2:E1000"), (INDIRECT("'"&D$1&"'!B2:B1000")=$B36) * (INDIRECT("'"&D$1&"'!C2:C1000")=$C36) ), 5, FALSE )=0, "", VLOOKUP( $A36, _xlfn._xlws.FILTER( INDIRECT("'"&D$1&"'!A2:E1000"), (INDIRECT("'"&D$1&"'!B2:B1000")=$B36) * (INDIRECT("'"&D$1&"'!C2:C1000")=$C36) ), 5, FALSE ) )} | E36: {=IF( VLOOKUP( $A36, _xlfn._xlws.FILTER( INDIRECT("'"&E$1&"'!A2:E1000"), (INDIRECT("'"&E$1&"'!B2:B1000")=$B36) * (INDIRECT("'"&E$1&"'!C2:C1000")=$C36) ), 5, FALSE )=0, "", VLOOKUP( $A36, _xlfn._xlws.FILTER( INDIRECT("'"&E$1&"'!A2:E1000"), (INDIRECT("'"&E$1&"'!B2:B1000")=$B36) * (INDIRECT("'"&E$1&"'!C2:C1000")=$C36) ), 5, FALSE ) )} | F36: {=IF( VLOOKUP( $A36, _xlfn._xlws.FILTER( INDIRECT("'"&F$1&"'!A2:E1000"), (INDIRECT("'"&F$1&"'!B2:B1000")=$B36) * (INDIRECT("'"&F$1&"'!C2:C1000")=$C36) ), 5, FALSE )=0, "", VLOOKUP( $A36, _xlfn._xlws.FILTER( INDIRECT("'"&F$1&"'!A2:E1000"), (INDIRECT("'"&F$1&"'!B2:B1000")=$B36) * (INDIRECT("'"&F$1&"'!C2:C1000")=$C36) ), 5, FALSE ) )}
A37: Gustavo | B37: Tupassi | C37: 1 | D37: {=IF( VLOOKUP( $A37, _xlfn._xlws.FILTER( INDIRECT("'"&D$1&"'!A2:E1000"), (INDIRECT("'"&D$1&"'!B2:B1000")=$B37) * (INDIRECT("'"&D$1&"'!C2:C1000")=$C37) ), 5, FALSE )=0, "", VLOOKUP( $A37, _xlfn._xlws.FILTER( INDIRECT("'"&D$1&"'!A2:E1000"), (INDIRECT("'"&D$1&"'!B2:B1000")=$B37) * (INDIRECT("'"&D$1&"'!C2:C1000")=$C37) ), 5, FALSE ) )} | E37: {=IF( VLOOKUP( $A37, _xlfn._xlws.FILTER( INDIRECT("'"&E$1&"'!A2:E1000"), (INDIRECT("'"&E$1&"'!B2:B1000")=$B37) * (INDIRECT("'"&E$1&"'!C2:C1000")=$C37) ), 5, FALSE )=0, "", VLOOKUP( $A37, _xlfn._xlws.FILTER( INDIRECT("'"&E$1&"'!A2:E1000"), (INDIRECT("'"&E$1&"'!B2:B1000")=$B37) * (INDIRECT("'"&E$1&"'!C2:C1000")=$C37) ), 5, FALSE ) )} | F37: {=IF( VLOOKUP( $A37, _xlfn._xlws.FILTER( INDIRECT("'"&F$1&"'!A2:E1000"), (INDIRECT("'"&F$1&"'!B2:B1000")=$B37) * (INDIRECT("'"&F$1&"'!C2:C1000")=$C37) ), 5, FALSE )=0, "", VLOOKUP( $A37, _xlfn._xlws.FILTER( INDIRECT("'"&F$1&"'!A2:E1000"), (INDIRECT("'"&F$1&"'!B2:B1000")=$B37) * (INDIRECT("'"&F$1&"'!C2:C1000")=$C37) ), 5, FALSE ) )}
A38: Gustavo | B38: Ubirata | C38: 1 | D38: {=IF( VLOOKUP( $A38, _xlfn._xlws.FILTER( INDIRECT("'"&D$1&"'!A2:E1000"), (INDIRECT("'"&D$1&"'!B2:B1000")=$B38) * (INDIRECT("'"&D$1&"'!C2:C1000")=$C38) ), 5, FALSE )=0, "", VLOOKUP( $A38, _xlfn._xlws.FILTER( INDIRECT("'"&D$1&"'!A2:E1000"), (INDIRECT("'"&D$1&"'!B2:B1000")=$B38) * (INDIRECT("'"&D$1&"'!C2:C1000")=$C38) ), 5, FALSE ) )} | E38: {=IF( VLOOKUP( $A38, _xlfn._xlws.FILTER( INDIRECT("'"&E$1&"'!A2:E1000"), (INDIRECT("'"&E$1&"'!B2:B1000")=$B38) * (INDIRECT("'"&E$1&"'!C2:C1000")=$C38) ), 5, FALSE )=0, "", VLOOKUP( $A38, _xlfn._xlws.FILTER( INDIRECT("'"&E$1&"'!A2:E1000"), (INDIRECT("'"&E$1&"'!B2:B1000")=$B38) * (INDIRECT("'"&E$1&"'!C2:C1000")=$C38) ), 5, FALSE ) )} | F38: {=IF( VLOOKUP( $A38, _xlfn._xlws.FILTER( INDIRECT("'"&F$1&"'!A2:E1000"), (INDIRECT("'"&F$1&"'!B2:B1000")=$B38) * (INDIRECT("'"&F$1&"'!C2:C1000")=$C38) ), 5, FALSE )=0, "", VLOOKUP( $A38, _xlfn._xlws.FILTER( INDIRECT("'"&F$1&"'!A2:E1000"), (INDIRECT("'"&F$1&"'!B2:B1000")=$B38) * (INDIRECT("'"&F$1&"'!C2:C1000")=$C38) ), 5, FALSE ) )}
A40: Regional | B40: Municípios | C40: UVR | D40: Form 1 - Município | E40: Form 2 - UVR | F40: Form 3 - Empreendimento
A41: Larissa | B41: Foz do Iguaçu | C41: 1 | D41: {=IF( VLOOKUP( $A41, _xlfn._xlws.FILTER( INDIRECT("'"&D$40&"'!A2:E1000"), (INDIRECT("'"&D$40&"'!B2:B1000")=$B41) * (INDIRECT("'"&D$40&"'!C2:C1000")=$C41) ), 5, FALSE )=0, "", VLOOKUP( $A41, _xlfn._xlws.FILTER( INDIRECT("'"&D$40&"'!A2:E1000"), (INDIRECT("'"&D$40&"'!B2:B1000")=$B41) * (INDIRECT("'"&D$40&"'!C2:C1000")=$C41) ), 5, FALSE ) )} | E41: {=IF( VLOOKUP( $A41, _xlfn._xlws.FILTER( INDIRECT("'"&E$40&"'!A2:E1000"), (INDIRECT("'"&E$40&"'!B2:B1000")=$B41) * (INDIRECT("'"&E$40&"'!C2:C1000")=$C41) ), 5, FALSE )=0, "", VLOOKUP( $A41, _xlfn._xlws.FILTER( INDIRECT("'"&E$40&"'!A2:E1000"), (INDIRECT("'"&E$40&"'!B2:B1000")=$B41) * (INDIRECT("'"&E$40&"'!C2:C1000")=$C41) ), 5, FALSE ) )} | F41: {=IF( VLOOKUP( $A41, _xlfn._xlws.FILTER( INDIRECT("'"&F$40&"'!A2:E1000"), (INDIRECT("'"&F$40&"'!B2:B1000")=$B41) * (INDIRECT("'"&F$40&"'!C2:C1000")=$C41) ), 5, FALSE )=0, "", VLOOKUP( $A41, _xlfn._xlws.FILTER( INDIRECT("'"&F$40&"'!A2:E1000"), (INDIRECT("'"&F$40&"'!B2:B1000")=$B41) * (INDIRECT("'"&F$40&"'!C2:C1000")=$C41) ), 5, FALSE ) )}
A42: Larissa | B42: Foz do Iguaçu | C42: 2 | D42: {=IF( VLOOKUP( $A42, _xlfn._xlws.FILTER( INDIRECT("'"&D$40&"'!A2:E1000"), (INDIRECT("'"&D$40&"'!B2:B1000")=$B42) * (INDIRECT("'"&D$40&"'!C2:C1000")=$C42) ), 5, FALSE )=0, "", VLOOKUP( $A42, _xlfn._xlws.FILTER( INDIRECT("'"&D$40&"'!A2:E1000"), (INDIRECT("'"&D$40&"'!B2:B1000")=$B42) * (INDIRECT("'"&D$40&"'!C2:C1000")=$C42) ), 5, FALSE ) )} | E42: {=IF( VLOOKUP( $A42, _xlfn._xlws.FILTER( INDIRECT("'"&E$40&"'!A2:E1000"), (INDIRECT("'"&E$40&"'!B2:B1000")=$B42) * (INDIRECT("'"&E$40&"'!C2:C1000")=$C42) ), 5, FALSE )=0, "", VLOOKUP( $A42, _xlfn._xlws.FILTER( INDIRECT("'"&E$40&"'!A2:E1000"), (INDIRECT("'"&E$40&"'!B2:B1000")=$B42) * (INDIRECT("'"&E$40&"'!C2:C1000")=$C42) ), 5, FALSE ) )} | F42: {=IF( VLOOKUP( $A42, _xlfn._xlws.FILTER( INDIRECT("'"&F$40&"'!A2:E1000"), (INDIRECT("'"&F$40&"'!B2:B1000")=$B42) * (INDIRECT("'"&F$40&"'!C2:C1000")=$C42) ), 5, FALSE )=0, "", VLOOKUP( $A42, _xlfn._xlws.FILTER( INDIRECT("'"&F$40&"'!A2:E1000"), (INDIRECT("'"&F$40&"'!B2:B1000")=$B42) * (INDIRECT("'"&F$40&"'!C2:C1000")=$C42) ), 5, FALSE ) )}
A43: Larissa | B43: Foz do Iguaçu | C43: 3 | D43: {=IF( VLOOKUP( $A43, _xlfn._xlws.FILTER( INDIRECT("'"&D$40&"'!A2:E1000"), (INDIRECT("'"&D$40&"'!B2:B1000")=$B43) * (INDIRECT("'"&D$40&"'!C2:C1000")=$C43) ), 5, FALSE )=0, "", VLOOKUP( $A43, _xlfn._xlws.FILTER( INDIRECT("'"&D$40&"'!A2:E1000"), (INDIRECT("'"&D$40&"'!B2:B1000")=$B43) * (INDIRECT("'"&D$40&"'!C2:C1000")=$C43) ), 5, FALSE ) )} | E43: {=IF( VLOOKUP( $A43, _xlfn._xlws.FILTER( INDIRECT("'"&E$40&"'!A2:E1000"), (INDIRECT("'"&E$40&"'!B2:B1000")=$B43) * (INDIRECT("'"&E$40&"'!C2:C1000")=$C43) ), 5, FALSE )=0, "", VLOOKUP( $A43, _xlfn._xlws.FILTER( INDIRECT("'"&E$40&"'!A2:E1000"), (INDIRECT("'"&E$40&"'!B2:B1000")=$B43) * (INDIRECT("'"&E$40&"'!C2:C1000")=$C43) ), 5, FALSE ) )} | F43: {=IF( VLOOKUP( $A43, _xlfn._xlws.FILTER( INDIRECT("'"&F$40&"'!A2:E1000"), (INDIRECT("'"&F$40&"'!B2:B1000")=$B43) * (INDIRECT("'"&F$40&"'!C2:C1000")=$C43) ), 5, FALSE )=0, "", VLOOKUP( $A43, _xlfn._xlws.FILTER( INDIRECT("'"&F$40&"'!A2:E1000"), (INDIRECT("'"&F$40&"'!B2:B1000")=$B43) * (INDIRECT("'"&F$40&"'!C2:C1000")=$C43) ), 5, FALSE ) )}
...

Sheet Form 1 - Município
A1: Regional | B1: Município | C1: UVR | D1: Técnico de UVR | E1: Situação | F1: Data de Envio | G1: Validado pelo Regional | H1: Observações | I1: Formulários para Deletar (ID) | J1: Validado Equip de TI | K1: Resposta Equipe de TI
A2: Gabriel | B2: Altônia | C2: 1 | D2: Paula Tatiana Santana Vechi | E2: Enviado | F2: 09/07/2025 | G2: Sim | H2: correções em: Qual a despesa anual com os serviços de coleta (convencional, seletiva) no município? se não ok | J2: Não
A3: Bianca | B3: Anahy | C3: 1 | D3: Willian de Oliveira Lino | E3: Atrasado | G3: Não | J3: Não
A4: Gustavo | B4: Assis Chateaubriand | C4: 1 | D4: Gisele Cássia Tamparowsky de Oliveira | E4: Enviado | F4: 09/07/2025 | G4: Sim | H4: ok | J4: Não
A5: Bianca | B5: Boa Vista da Aparecida | C5: 1 | D5: Marcos Gabriel Franciosi Borges | E5: Enviado | F5: 21/03/2025 | G5: Sim | J5: Não
A6: Bianca | B6: Braganey | C6: 1 | D6: Chayla Bianca Gazoli | E6: Enviado | F6: 10/04/2025 | G6: Não | J6: Não
A7: Gustavo | B7: Brasilândia do Sul | C7: 1 | D7: Solange Maria Masqueti | E7: Enviado | F7: 20/03/2025 | G7: Sim | H7: Preencher Qual a despesa anual com os serviços de coleta | J7: Não
A8: Gustavo | B8: Cafelândia | C8: 1 | D8: Cristiane Petry Vieira | E8: Enviado | F8: 20/03/2025 | G8: Não | H8: 09/04 - Dados incorretos de arrecadação e despesa - formulário aba 5 - informações financeiras do município | J8: Não
A9: Bianca | B9: Campo Bonito | C9: 1 | D9: Diego Hemerich | E9: Atrasado | G9: Não | J9: Não
A10: Valquiria | B10: Capitão Leonidas Marques | C10: 1 | D10: Tatiane Girardi | E10: Enviado | F10: 06/03/2025 | G10: Sim | J10: Não
A11: Valquiria | B11: Cascavel | C11: 1 | D11: Edson Batista de Castro | E11: Duplicado | F11: 10/04/2025, 15/05/2025 | G11: Não | J11: Não
A12: Valquiria | B12: Cascavel | C12: 2 | D12: Gabriela Fernanda Sandri | E12: Duplicado | F12: 10/04/2025, 15/05/2025 | G12: Não | J12: Não
A13: Valquiria | B13: Cascavel | C13: 3 | D13: Eduarda Rohden Donasolo | E13: Duplicado | F13: 10/04/2025, 15/05/2025 | G13: Não | J13: Não
A14: Valquiria | B14: Cascavel | C14: 4 | D14: Mauricio Pinto de Lima | E14: Duplicado | F14: 10/04/2025, 15/05/2025 | G14: Não | J14: Não
A15: Valquiria | B15: Cascavel | C15: 5 | D15: Débora Laize Lampert Gnass | E15: Duplicado | F15: 10/04/2025, 15/05/2025 | G15: Não | J15: Não
A16: Valquiria | B16: Cascavel | C16: 6 | E16: Duplicado | F16: 10/04/2025, 15/05/2025 | G16: Não | J16: Não
A17: Bianca | B17: Catanduvas | C17: 1 | D17: Cristina Harumi Enokida | E17: Enviado | F17: 12/08/2025 | G17: Não | H17: Está com dificuldade de salvar o rascunho do formulário 1 | J17: Não
A18: Valquiria | B18: Céu Azul | C18: 1 | D18: Douglas de Mattia | E18: Enviado | F18: 26/02/2025 | G18: Sim | J18: Não
A19: Bianca | B19: Corbélia | C19: 1 | D19: Vanderson Pasetti | E19: Atrasado | G19: Não | J19: Não
A20: Luana | B20: Diamante d'Oeste | C20: 1 | D20: Bruna Schneider Guimarães | E20: Enviado | F20: 19/03/2025 | G20: Sim | J20: Não
A21: Bianca | B21: Diamante do Sul | C21: 1 | D21: Keilla Avezedo | E21: Enviado | F21: 10/03/2025 | G21: Sim | J21: Não
A22: Luana | B22: Entre Rios do Oeste | C22: 1 | D22: Carmen Maria Stein Weiler | E22: Enviado | F22: 05/08/2025 | G22: Sim | J22: Não
A23: Gustavo | B23: Formosa do Oeste | C23: 1 | D23: Thiago Varaschim Cenci | E23: Enviado | F23: 15/04/2025 | G23: Sim | J23: Não
A24: Larissa | B24: Foz do Iguaçu | C24: 1 | D24: Éber Alexandre Nascimento Araújo | E24: Enviado | F24: 08/08/2025 | G24: Sim | J24: Não
A25: Larissa | B25: Foz do Iguaçu | C25: 2 | D25: Andrea Carla Winkelmann | E25: Enviado | F25: 08/08/2025 | G25: Sim | H25: corrigir aba 7 (não há compostagem) | J25: Não
A26: Larissa | B26: Foz do Iguaçu | C26: 3 | D26: Lorizete de Andrade | E26: Enviado | F26: 08/08/2025 | G26: Sim | H26: corrigir aba 7 (não há compostagem) | J26: Não
A27: Larissa | B27: Foz do Iguaçu | C27: 4 | D27: Andressa Maia | E27: Enviado | F27: 08/08/2025 | G27: Sim | H27: corrigir aba 7 (não há compostagem) | J27: Não
A28: Larissa | B28: Foz do Iguaçu | C28: 5 | D28: Lucas Correia de Souza | E28: Enviado | F28: 08/08/2025 | G28: Sim | H28: corrigir aba 7 (não há compostagem) | J28: Não
A29: Larissa | B29: Foz do Iguaçu | C29: 6 | D29: Jose Francisco Mariano de Faria Filho | E29: Enviado | F29: 08/08/2025 | G29: Sim | H29: corrigir aba 7 (não há compostagem) | J29: Não
A30: Larissa | B30: Foz do Iguaçu | C30: 7 | D30: Pedro Henrique Mariano de Faria | E30: Enviado | F30: 08/08/2025 | G30: Sim | H30: corrigir aba 7 (não há compostagem) | J30: Não
A31: Larissa | B31: Foz do Iguaçu | C31: 8 | D31: Renata Aparecida de Souza | E31: Enviado | F31: 08/08/2025 | G31: Sim | H31: corrigir aba 7 (não há compostagem) | J31: Não
A32: Larissa | B32: Foz do Iguaçu | C32: 9 | D32: Maria Eduarda dos Santos Arias | E32: Enviado | F32: 08/08/2025 | G32: Sim | H32: corrigir aba 7 (não há compostagem) | J32: Não
A33: Gabriel | B33: Francisco Alves | C33: 1 | D33: Paulo Rogerio Hiroshi Fujii | E33: Atrasado | G33: Não | J33: Não
A34: Gabriel | B34: Guaira | C34: 1 | D34: Marlene R. Oliveira Dallacosta | E34: Atrasado | G34: Não | J34: Não
A35: Bianca | B35: Guaraniacu | C35: 1 | D35: Vitolor dos Santos Almeida | E35: Enviado | F35: 02/04/2025 | G35: Não | H35: Necessário ajustes pág 4, 5 e 6 | I35: ID98 | J35: Sim | K35: Deletado 98
A36: Bianca | B36: Ibema | C36: 1 | D36: Kelly Jackeline Silva do Valle | E36: Enviado | F36: 24/03/2025 | G36: Sim | H36: pág 6, a frequência de coleta urbana e rural é em porcentagem e não em dias. | J36: Não
A37: Bianca | B37: Iguatu | C37: 1 | D37: Felipe Carvalho Zydek | E37: Enviado | F37: 13/03/2025 | G37: Sim | H37: Pág 5, vc não conseguiu i valor da taxa de lixo recebida em 2024 pela prefeitura. Pág 6, a frequência das coletas é porcentagem, não em dia. | J37: Não
